Workbook
Name _1Q_AVERAGE: MIP!$AH$8:$AH$62
Name _1Q_COL_1: MIP!$Y$8:$Y$62
Name _1Q_COL_10: MIP!#REF!
Name _1Q_COL_11: MIP!$AE$8:$AE$62
Name _1Q_COL_12: MIP!$AF$8:$AF$62
Name _1Q_COL_2: MIP!#REF!
Name _1Q_COL_3: MIP!$Z$8:$Z$62
Name _1Q_COL_4: MIP!#REF!
Name _1Q_COL_5: MIP!$AA$8:$AA$62
Name _1Q_COL_6: MIP!$AB$8:$AB$62
Name _1Q_COL_7: MIP!$AC$8:$AC$62
Name _1Q_COL_8: MIP!#REF!
Name _1Q_COL_9: MIP!$AD$8:$AD$62
Name _1Q_SEX: MIP!$X$8:$X$62
Name _2Q_AVERAGE: MIP!$AH$75:$AH$129
Name _2Q_COL_1: MIP!$Y$75:$Y$129
Name _2Q_COL_10: MIP!#REF!
Name _2Q_COL_11: MIP!$AE$75:$AE$129
Name _2Q_COL_12: MIP!$AF$75:$AF$129
Name _2Q_COL_2: MIP!#REF!
Name _2Q_COL_3: MIP!$Z$75:$Z$129
Name _2Q_COL_4: MIP!#REF!
Name _2Q_COL_5: MIP!$AA$75:$AA$129
Name _2Q_COL_6: MIP!$AB$75:$AB$129
Name _2Q_COL_7: MIP!$AC$75:$AC$129
Name _2Q_COL_8: MIP!#REF!
Name _2Q_COL_9: MIP!$AD$75:$AD$129
Name _2Q_SEX: MIP!$X$75:$X$129
Name _3Q_AVERAGE: MIP!#REF!
Name _3Q_COL_1: MIP!#REF!
Name _3Q_COL_10: MIP!#REF!
Name _3Q_COL_11: MIP!#REF!
Name _3Q_COL_12: MIP!#REF!
Name _3Q_COL_2: MIP!#REF!
Name _3Q_COL_3: MIP!#REF!
Name _3Q_COL_4: MIP!#REF!
Name _3Q_COL_5: MIP!#REF!
Name _3Q_COL_6: MIP!#REF!
Name _3Q_COL_7: MIP!#REF!
Name _3Q_COL_8: MIP!#REF!
Name _3Q_COL_9: MIP!#REF!
Name _3Q_SEX: MIP!#REF!
Name _4Q_AVERAGE: MIP!#REF!
Name _4Q_COL_1: MIP!#REF!
Name _4Q_COL_10: MIP!#REF!
Name _4Q_COL_11: MIP!#REF!
Name _4Q_COL_12: MIP!#REF!
Name _4Q_COL_2: MIP!#REF!
Name _4Q_COL_3: MIP!#REF!
Name _4Q_COL_4: MIP!#REF!
Name _4Q_COL_5: MIP!#REF!
Name _4Q_COL_6: MIP!#REF!
Name _4Q_COL_7: MIP!#REF!
Name _4Q_COL_8: MIP!#REF!
Name _4Q_COL_9: MIP!#REF!
Name _4Q_SEX: MIP!#REF!
Name _Rang11B: #REF!
Name _Rang11C: #REF!
Name _Rang11D: #REF!
Name _Rang11E: #REF!

Sheet GI
A1: GRADE | D1: SHEBA ACADEMY | G1: # | H1: Students' Names | I1: Sex | J1: Age | K1: M | L1: F | M1: T
G2: 1 | H2: Amanuel Hagos Tesfay | I2: M | K2: =COUNTIF($I$2:$I$56, "M") -> 26 | L2: =COUNTIF($I$2:$I$56, "f") -> 17 | M2: =SUM(K2:L2) -> 43 | N2: PRO
A3: 11 | C3: D | G3: 2 | H3: Beamlak Sultan Weldegebriel | I3: M | N3: PRO
G4: 3 | H4: Betelihim Kalayu Mamo | I4: F | N4: PRO
A5: Subject | C5: Teacher's Name | G5: 4 | H5: Bethelhem Teklay Weldegerima | I5: F | N5: PRO
G6: 5 | H6: Bilen Mesfin Taye | I6: F | N6: PRO
A7: 1 | B7: English | C7: Teklay Haile | G7: 6 | H7: Biruk Mulat Kiros | I7: M | N7: PRO
A8: 2 | B8: - | G8: 7 | H8: Bruk Gebreabyezgi Gebreselassie | I8: M | N8: PRO
A9: 3 | B9: Mathematics | C9: Berhe Hagos | G9: 8 | H9: Dagim Hagos Mehari | I9: M | N9: PRO
A10: 4 | B10: - | G10: 9 | H10: Danait Alem Haile | I10: F | N10: PRO
A11: 5 | B11: History | C11: Biniam Desta | G11: 10 | H11: Daniel Alem Beyene | I11: M | N11: PRO
A12: 6 | B12: Geography | C12: G/michael Kidane | G12: 11 | H12: Dawit Gebegziabher Teklay | I12: M | N12: PRO
A13: 7 | B13: Economics | C13: Kahsay G/medhin | G13: 12 | H13: Ibrahim Ahmedin Ebrahim | I13: M | N13: PRO
A14: 8 | B14: - | G14: 13 | H14: Eldana Tewelde Negash | I14: F | N14: PRO
A15: 9 | B15: ICT | C15: Hagos Redae | G15: 14 | H15: Elilta Asay Eyasu | I15: F | N15: PRO
A16: 10 | B16: - | G16: 15 | H16: Emebet Haftay Gebremichael | I16: F | N16: PRO
A17: 11 | B17: Accounting and finance | C17: Tadele Berhe | G17: 16 | H17: Ermiyas Gebremeskel Hailu | I17: M | N17: PRO
A18: 12 | B18: - | G18: 17 | H18: Esrom Amanuel Tsegay | I18: M | N18: PRO
A19: 13 | B19: - | G19: 18 | H19: Eyorsalem Afera Gebremedhin | I19: F | N19: PRO
A20: 14 | B20: - | G20: 19 | H20: Fasil Alem Kahsay | I20: M | N20: PRO
A21: 15 | B21: - | G21: 20 | H21: Hassen Abdelruhman Salih | I21: M | N21: PRO
G22: 21 | H22: Heldana Mengstu Mebrahtu | I22: F | N22: PRO
A23: Number of Students | D23: Academic Director's Name | E23: Homeroom Teacher's Name | G23: 22 | H23: Hilina Aregawi Abrha | I23: F | N23: PRO
G24: 23 | H24: Kaleab Haile Kahsay | I24: M | N24: PRO
A25: First Quarter: | C25: =$M$2 -> 43 | D25: Mr. Brhane Yohanes | E25: Biniam Desta | G25: 24 | H25: Kalkidan Haile Berhe | I25: F | N25: PRO
A26: Second Quarter: | C26: =$M$2 -> 43 | D26: Mr. Brhane Yohanes | E26: Biniam Desta | G26: 25 | H26: Kidus Tadesse Yewegalet | I26: M | N26: PRO
A27: First Semester: | C27: =$M$2 -> 43 | D27: Mr. Brhane Yohanes | E27: Biniam Desta | G27: 26 | H27: Lidiya Mulu Gebreegzabher | I27: F | N27: PRO
A28: Third Quarter: | C28: =$M$2 -> 43 | D28: Mr. Brhane Yohanes | E28: Biniam Desta | G28: 27 | H28: Menkem Solomon Yihdego | I28: M | N28: PRO
A29: Fourth Quarter: | C29: =$M$2 -> 43 | D29: Mr. Brhane Yohanes | E29: Biniam Desta | G29: 28 | H29: Mewael Semere Tewelde | I29: M | N29: PRO
A30: Second Semester: | C30: =$M$2 -> 43 | D30: Mr. Brhane Yohanes | E30: Biniam Desta | G30: 29 | H30: Mikiyas Engida Mesfin | I30: M | N30: PRO
A31: Yearly Average: | C31: =$M$2 -> 43 | D31: Mr. Brhane Yohanes | E31: Biniam Desta | G31: 30 | H31: Nahom Gobezay Beyene | I31: M | N31: PRO
G32: 31 | H32: Nebyu Dawit Tadesse | I32: M | N32: PRO
G33: 32 | H33: Rahwa Luel Birhane | I33: F | N33: PRO
A34: Academic Year | C34: 2025/26 G.C | D34: 2018 ዓ/ም | G34: 33 | H34: Raniya Jemal Gidey | I34: F | N34: PRO
A35: =CONCATENATE($D$1," ", $D$35) -> SHEBA ACADEMY 3rd Cycle | D35: 3rd Cycle | G35: 34 | H35: Samrawit Weldeslassie Kidane | I35: F | N35: PRO
A36: =CONCATENATE("STUDENTS' ROSTER GRADE ", $A$3) -> STUDENTS' ROSTER GRADE 11 | D36: Sub-Head Title: Roster | G36: 35 | H36: Samson Tekle Belay | I36: M | N36: PRO
A37: Temporary Grade Report | D37: Sub-Head Title: GRF | G37: 36 | H37: Sinados Solomon Kiflehadera | I37: M | N37: PRO
A38: =CONCATENATE($D$1," ", $C$34, " ACADEMEC YEAR") -> SHEBA ACADEMY 2025/26 G.C ACADEMEC YEAR | D38: Head-Title: MIP | G38: 37 | H38: Yeabsira Rezene Gebrecherkos | I38: M | N38: PRO
A39: 1st SEMESTER ROSTER | G39: 38 | H39: Yohannes Gebregergis Weldegebriel | I39: M | N39: PRO
A40: 2nd SEMESTER ROSTER | G40: 39 | H40: Yohanns Gebremedhin Aregawi | I40: M | N40: PRO
...

Sheet MIP
A1: =GI!$D$1 -> SHEBA ACADEMY | F1: è | I1: =GI!$D$1 -> SHEBA ACADEMY | N1: è
A3: =CONCATENATE(GI!$D$35," & General Secondary School") -> 3rd Cycle & General Secondary School | I3: =CONCATENATE(GI!$D$35," & General Secondary School") -> 3rd Cycle & General Secondary School | V3: =CONCATENATE(GI!$A$3, " ", GI!$C$3) -> 11 D | X3: =GI!$A$38 -> SHEBA ACADEMY 2025/26 G.C ACADEMEC YEAR | AK3: ê | AL3: =CONCATENATE(GI!$D$1, " GRADE ", GI!$A$3,GI!$C$3," ", GI!$B$54) -> SHEBA ACADEMY GRADE 11D 1st SEMESTER RESULT STATISTICS
A4: Mark Transfer Sheet | I4: Mark Transfer Sheet | BB4: =GI!$A$3&GI!$C$3 -> 11D
A5: 1 | C5: Grade: | D5: =GI!$A$3&" "&GI!$C$3 -> 11 D | F5: ê | H5: =$H$942 -> S | I5: 1 | K5: Grade: | L5: =GI!$A$3&" "&GI!$C$3 -> 11 D | N5: ê | P5: =$H$942 -> S | Q5: =$H$942 -> S | X5: =GI!$A$39 -> 1st SEMESTER ROSTER | AT5: MALE: | AU5: =COUNTIFS(_1Q_SEX, "M") -> 26 | AV5: FEMALE: | AW5: =COUNTIFS(_1Q_SEX, "F") -> 17 | AX5: TOTAL: | AY5: =SUM(AU5,AW5) -> 43 | BA5: FORMULAS
C6: Subject: | D6: =UPPER(GI!$B$7) -> ENGLISH | K6: Subject: | L6: =UPPER(GI!$B$7) -> ENGLISH | AL6: SUBJECT | AM6: =$BA$6 &" " & $BC$6 -> >=1 <55 | AP6: =$BA$7 &" " & $BC$7 -> >=55 <75 | AS6: =$BA$8 &" " & $BC$8 -> >=75 <85 | AV6: =$BA$9 &" " & $BC$9 -> >=85 <=100 | AY6: TOTAL | BA6: >=1 | BC6: <55
B7: =GI!$A$34& ":" -> Academic Year: | C7: =GI!$C$34 -> 2025/26 G.C | D7: 1st SEMESTER | J7: =GI!$A$34& ":" -> Academic Year: | K7: =GI!$C$34 -> 2025/26 G.C | L7: 2nd SEMESTER | V7: # | W7: =GI!$H$1 -> Students' Names | X7: SEX | Y7: =UPPER(LEFT(GI!$B$7, GI!$B$63)) -> ENG | Z7: =UPPER(LEFT(GI!$B$9, GI!$B$63)) -> MAT | AA7: =UPPER(LEFT(GI!$B$11, GI!$B$63)) -> HIS | AB7: =UPPER(LEFT(GI!$B$12, GI!$B$63)) -> GEO | AC7: =UPPER(LEFT(GI!$B$13, GI!$B$63)) -> ECO | AD7: =UPPER(LEFT(GI!$B$15, GI!$B$63)) -> ICT | AE7: =UPPER(LEFT(GI!$B$17, GI!$B$63)) -> ACC | AF7: =UPPER(LEFT(GI!$B$18, GI!$B$63)) -> - | AG7: TOTAL | AH7: AVERAGE | AI7: RANK | AJ7: STATUS | AM7: M | AN7: F | AO7: T | AP7: M | AQ7: F | AR7: T | AS7: M | AT7: F | AU7: T | AV7: M | AW7: F | AX7: T | BA7: >=55 | BC7: <75
A8: # | B8: =GI!$H$1 -> Students' Names | C8: Marks | I8: # | J8: =GI!$H$1 -> Students' Names | K8: Marks | V8: 1 | W8: =GI!$H$2 -> Amanuel Hagos Tesfay | X8: =GI!$I$2 -> M | Y8: =$R$10 -> 76 | Z8: =$R$144 -> 57 | AA8: =$R$277 -> 91 | AB8: =$R$344 -> 85 | AC8: =$R$411 -> 71 | AD8: =$R$545 -> 82 | AE8: =$R$679 -> 83 | AF8: =$R$746 -> 0 | AG8: =SUM(Y8:AE8) -> 545 | AH8: =AG8/7 -> 77.857143 | AI8: =RANK(AH8, _1Q_AVERAGE) -> 9 | AJ8: =IF(AH8>=GI!$B$64, "PRO", "DET") -> PRO | AL8: =UPPER(GI!$B$7) -> ENGLISH | AM8: =COUNTIFS(_1Q_COL_1, $BA$6, _1Q_COL_1, $BC$6, _1Q_SEX, "M") -> 2 | AN8: =COUNTIFS(_1Q_COL_1, $BA$6, _1Q_COL_1, $BC$6, _1Q_SEX, "F") -> 1 | AO8: =SUM(AM8:AN8) -> 3 | AP8: =COUNTIFS(_1Q_COL_1, $BA$7, _1Q_COL_1, $BC$7, _1Q_SEX, "M") -> 19 | AQ8: =COUNTIFS(_1Q_COL_1, $BA$7, _1Q_COL_1, $BC$7, _1Q_SEX, "F") -> 11 | AR8: =SUM(AP8:AQ8) -> 30 | AS8: =COUNTIFS(_1Q_COL_1, $BA$8, _1Q_COL_1, $BC$8, _1Q_SEX, "M") -> 4 | AT8: =COUNTIFS(_1Q_COL_1, $BA$8, _1Q_COL_1, $BC$8, _1Q_SEX, "F") -> 5 | AU8: =SUM(AS8:AT8) -> 9 | AV8: =COUNTIFS(_1Q_COL_1, $BA$9, _1Q_COL_1, $BC$9, _1Q_SEX, "M") -> 1 | AW8: =COUNTIFS(_1Q_COL_1, $BA$9, _1Q_COL_1, $BC$9, _1Q_SEX, "F") -> 0 | AX8: =SUM(AV8:AW8) -> 1 | AY8: =SUM(AO8,AR8,AU8,AX8) -> 43 | BA8: >=75 | BC8: <85
C9: 0.4 | D9: 0.6 | E9: 1 | K9: 0.4 | L9: 0.6 | M9: =SUM(K9:L9) -> 1 | R9: =$D$7 -> 1st SEMESTER | S9: =$L$7 -> 2nd SEMESTER | T9: SEMESTER-I | V9: 2 | W9: =GI!$H$3 -> Beamlak Sultan Weldegebriel | X9: =GI!$I$3 -> M | Y9: =$R$11 -> 67 | Z9: =$R$145 -> 53 | AA9: =$R$278 -> 67 | AB9: =$R$345 -> 71 | AC9: =$R$412 -> 68 | AD9: =$R$546 -> 85 | AE9: =$R$680 -> 78 | AF9: =$R$747 -> 0 | AG9: =SUM(Y9:AE9) -> 489 | AH9: =AG9/7 -> 69.857143 | AI9: =RANK(AH9, _1Q_AVERAGE) -> 24 | AJ9: =IF(AH9>=GI!$B$64, "PRO", "DET") -> PRO | AL9: PERCENTAG: | AM9: =AM8*100/$AU$5 -> 7.6923077 | AN9: =AN8*100/$AW$5 -> 5.8823529 | AO9: =AO8*100/$AY$5 -> 6.9767442 | AP9: =AP8*100/$AU$5 -> 73.076923 | AQ9: =AQ8*100/$AW$5 -> 64.705882 | AR9: =AR8*100/$AY$5 -> 69.767442 | AS9: =AS8*100/$AU$5 -> 15.384615 | AT9: =AT8*100/$AW$5 -> 29.411765 | AU9: =AU8*100/$AY$5 -> 20.930233 | AV9: =AV8*100/$AU$5 -> 3.8461538 | AW9: =AW8*100/$AW$5 -> 0 | AX9: =AX8*100/$AY$5 -> 2.3255814 | AY9: =SUM(AO9,AR9,AU9,AX9) -> 100 | BA9: >=85 | BC9: <=100
A10: 1 | B10: =GI!$H$2 -> Amanuel Hagos Tesfay | E10: 76 | F10: =IF(E10>100,"SKURRR~!!", IF(A10>GI!$M$2," ", IF($D$6="-", " ", IF(ISBLANK(E10),"FALSE","")))) | I10: 1 | J10: =GI!$H$2 -> Amanuel Hagos Tesfay | N10: =IF(M10>100,"SKURRR~!!", IF(I10>GI!$M$2," ", IF($L$6="-", " ", IF(ISBLANK(M10),"FALSE","")))) -> FALSE | R10: =E10 -> 76 | S10: =M10 -> 0 | T10: =AVERAGE(R10:S10) -> 38 | V10: 3 | W10: =GI!$H$4 -> Betelihim Kalayu Mamo | X10: =GI!$I$4 -> F | Y10: =$R$12 -> 59 | Z10: =$R$146 -> 65 | AA10: =$R$279 -> 68 | AB10: =$R$346 -> 79 | AC10: =$R$413 -> 62 | AD10: =$R$547 -> 93 | AE10: =$R$681 -> 76 | AF10: =$R$748 -> 0 | AG10: =SUM(Y10:AE10) -> 502 | AH10: =AG10/7 -> 71.714286 | AI10: =RANK(AH10, _1Q_AVERAGE) -> 20 | AJ10: =IF(AH10>=GI!$B$64, "PRO", "DET") -> PRO | AL10: =UPPER(GI!$B$8) -> -
A11: 2 | B11: =GI!$H$3 -> Beamlak Sultan Weldegebriel | E11: 67 | F11: =IF(E11>100,"SKURRR~!!", IF(A11>GI!$M$2," ", IF($D$6="-", " ", IF(ISBLANK(E11),"FALSE","")))) | I11: 2 | J11: =GI!$H$3 -> Beamlak Sultan Weldegebriel | N11: =IF(M11>100,"SKURRR~!!", IF(I11>GI!$M$2," ", IF($L$6="-", " ", IF(ISBLANK(M11),"FALSE","")))) -> FALSE | R11: =E11 -> 67 | S11: =M11 -> 0 | T11: =AVERAGE(R11:S11) -> 33.5 | V11: 4 | W11: =GI!$H$5 -> Bethelhem Teklay Weldegerima | X11: =GI!$I$5 -> F | Y11: =$R$13 -> 77 | Z11: =$R$147 -> 56 | AA11: =$R$280 -> 90 | AB11: =$R$347 -> 71 | AC11: =$R$414 -> 75 | AD11: =$R$548 -> 86 | AE11: =$R$682 -> 75 | AF11: =$R$749 -> 0 | AG11: =SUM(Y11:AE11) -> 530 | AH11: =AG11/7 -> 75.714286 | AI11: =RANK(AH11, _1Q_AVERAGE) -> 13 | AJ11: =IF(AH11>=GI!$B$64, "PRO", "DET") -> PRO | AL11: PERCENTAG:
A12: 3 | B12: =GI!$H$4 -> Betelihim Kalayu Mamo | E12: 59 | F12: =IF(E12>100,"SKURRR~!!", IF(A12>GI!$M$2," ", IF($D$6="-", " ", IF(ISBLANK(E12),"FALSE","")))) | I12: 3 | J12: =GI!$H$4 -> Betelihim Kalayu Mamo | N12: =IF(M12>100,"SKURRR~!!", IF(I12>GI!$M$2," ", IF($L$6="-", " ", IF(ISBLANK(M12),"FALSE","")))) -> FALSE | R12: =E12 -> 59 | S12: =M12 -> 0 | T12: =AVERAGE(R12:S12) -> 29.5 | V12: 5 | W12: =GI!$H$6 -> Bilen Mesfin Taye | X12: =GI!$I$6 -> F | Y12: =$R$14 -> 57 | Z12: =$R$148 -> 55 | AA12: =$R$281 -> 55 | AB12: =$R$348 -> 33 | AC12: =$R$415 -> 44 | AD12: =$R$549 -> 67 | AE12: =$R$683 -> 82 | AF12: =$R$750 -> 0 | AG12: =SUM(Y12:AE12) -> 393 | AH12: =AG12/7 -> 56.142857 | AI12: =RANK(AH12, _1Q_AVERAGE) -> 43 | AJ12: =IF(AH12>=GI!$B$64, "PRO", "DET") -> PRO | AL12: =UPPER(GI!$B$9) -> MATHEMATICS | AM12: =COUNTIFS(_1Q_COL_3, $BA$6, _1Q_COL_3, $BC$6, _1Q_SEX, "M") -> 6 | AN12: =COUNTIFS(_1Q_COL_3, $BA$6, _1Q_COL_3, $BC$6, _1Q_SEX, "F") -> 4 | AO12: =SUM(AM12:AN12) -> 10 | AP12: =COUNTIFS(_1Q_COL_3, $BA$7, _1Q_COL_3, $BC$7, _1Q_SEX, "M") -> 19 | AQ12: =COUNTIFS(_1Q_COL_3, $BA$7, _1Q_COL_3, $BC$7, _1Q_SEX, "F") -> 12 | AR12: =SUM(AP12:AQ12) -> 31 | AS12: =COUNTIFS(_1Q_COL_3, $BA$8, _1Q_COL_3, $BC$8, _1Q_SEX, "M") -> 0 | AT12: =COUNTIFS(_1Q_COL_3, $BA$8, _1Q_COL_3, $BC$8, _1Q_SEX, "F") -> 1 | AU12: =SUM(AS12:AT12) -> 1 | AV12: =COUNTIFS(_1Q_COL_3, $BA$9, _1Q_COL_3, $BC$9, _1Q_SEX, "M") -> 1 | AW12: =COUNTIFS(_1Q_COL_3, $BA$9, _1Q_COL_3, $BC$9, _1Q_SEX, "F") -> 0 | AX12: =SUM(AV12:AW12) -> 1 | AY12: =SUM(AO12,AR12,AU12,AX12) -> 43
A13: 4 | B13: =GI!$H$5 -> Bethelhem Teklay Weldegerima | E13: 77 | F13: =IF(E13>100,"SKURRR~!!", IF(A13>GI!$M$2," ", IF($D$6="-", " ", IF(ISBLANK(E13),"FALSE","")))) | I13: 4 | J13: =GI!$H$5 -> Bethelhem Teklay Weldegerima | N13: =IF(M13>100,"SKURRR~!!", IF(I13>GI!$M$2," ", IF($L$6="-", " ", IF(ISBLANK(M13),"FALSE","")))) -> FALSE | R13: =E13 -> 77 | S13: =M13 -> 0 | T13: =AVERAGE(R13:S13) -> 38.5 | V13: 6 | W13: =GI!$H$7 -> Biruk Mulat Kiros | X13: =GI!$I$7 -> M | Y13: =$R$15 -> 63 | Z13: =$R$149 -> 65 | AA13: =$R$282 -> 77 | AB13: =$R$349 -> 82 | AC13: =$R$416 -> 71 | AD13: =$R$550 -> 93 | AE13: =$R$684 -> 85 | AF13: =$R$751 -> 0 | AG13: =SUM(Y13:AE13) -> 536 | AH13: =AG13/7 -> 76.571429 | AI13: =RANK(AH13, _1Q_AVERAGE) -> 11 | AJ13: =IF(AH13>=GI!$B$64, "PRO", "DET") -> PRO | AL13: PERCENTAG: | AM13: =AM12*100/$AU$5 -> 23.076923 | AN13: =AN12*100/$AW$5 -> 23.529412 | AO13: =AO12*100/$AY$5 -> 23.255814 | AP13: =AP12*100/$AU$5 -> 73.076923 | AQ13: =AQ12*100/$AW$5 -> 70.588235 | AR13: =AR12*100/$AY$5 -> 72.093023 | AS13: =AS12*100/$AU$5 -> 0 | AT13: =AT12*100/$AW$5 -> 5.8823529 | AU13: =AU12*100/$AY$5 -> 2.3255814 | AV13: =AV12*100/$AU$5 -> 3.8461538 | AW13: =AW12*100/$AW$5 -> 0 | AX13: =AX12*100/$AY$5 -> 2.3255814 | AY13: =SUM(AO13,AR13,AU13,AX13) -> 100
A14: 5 | B14: =GI!$H$6 -> Bilen Mesfin Taye | E14: 57 | F14: =IF(E14>100,"SKURRR~!!", IF(A14>GI!$M$2," ", IF($D$6="-", " ", IF(ISBLANK(E14),"FALSE","")))) | I14: 5 | J14: =GI!$H$6 -> Bilen Mesfin Taye | N14: =IF(M14>100,"SKURRR~!!", IF(I14>GI!$M$2," ", IF($L$6="-", " ", IF(ISBLANK(M14),"FALSE","")))) -> FALSE | R14: =E14 -> 57 | S14: =M14 -> 0 | T14: =AVERAGE(R14:S14) -> 28.5 | V14: 7 | W14: =GI!$H$8 -> Bruk Gebreabyezgi Gebreselassie | X14: =GI!$I$8 -> M | Y14: =$R$16 -> 53 | Z14: =$R$150 -> 48 | AA14: =$R$283 -> 59 | AB14: =$R$350 -> 59 | AC14: =$R$417 -> 56 | AD14: =$R$551 -> 60 | AE14: =$R$685 -> 60 | AF14: =$R$752 -> 0 | AG14: =SUM(Y14:AE14) -> 395 | AH14: =AG14/7 -> 56.428571 | AI14: =RANK(AH14, _1Q_AVERAGE) -> 42 | AJ14: =IF(AH14>=GI!$B$64, "PRO", "DET") -> PRO | AL14: =UPPER(GI!$B$10) -> -
A15: 6 | B15: =GI!$H$7 -> Biruk Mulat Kiros | E15: 63 | F15: =IF(E15>100,"SKURRR~!!", IF(A15>GI!$M$2," ", IF($D$6="-", " ", IF(ISBLANK(E15),"FALSE","")))) | I15: 6 | J15: =GI!$H$7 -> Biruk Mulat Kiros | N15: =IF(M15>100,"SKURRR~!!", IF(I15>GI!$M$2," ", IF($L$6="-", " ", IF(ISBLANK(M15),"FALSE","")))) -> FALSE | R15: =E15 -> 63 | S15: =M15 -> 0 | T15: =AVERAGE(R15:S15) -> 31.5 | V15: 8 | W15: =GI!$H$9 -> Dagim Hagos Mehari | X15: =GI!$I$9 -> M | Y15: =$R$17 -> 66 | Z15: =$R$151 -> 58 | AA15: =$R$284 -> 73 | AB15: =$R$351 -> 73 | AC15: =$R$418 -> 61 | AD15: =$R$552 -> 80 | AE15: =$R$686 -> 75 | AF15: =$R$753 -> 0 | AG15: =SUM(Y15:AE15) -> 486 | AH15: =AG15/7 -> 69.428571 | AI15: =RANK(AH15, _1Q_AVERAGE) -> 25 | AJ15: =IF(AH15>=GI!$B$64, "PRO", "DET") -> PRO | AL15: PERCENTAG:
A16: 7 | B16: =GI!$H$8 -> Bruk Gebreabyezgi Gebreselassie | E16: 53 | F16: =IF(E16>100,"SKURRR~!!", IF(A16>GI!$M$2," ", IF($D$6="-", " ", IF(ISBLANK(E16),"FALSE","")))) | I16: 7 | J16: =GI!$H$8 -> Bruk Gebreabyezgi Gebreselassie | N16: =IF(M16>100,"SKURRR~!!", IF(I16>GI!$M$2," ", IF($L$6="-", " ", IF(ISBLANK(M16),"FALSE","")))) -> FALSE | R16: =E16 -> 53 | S16: =M16 -> 0 | T16: =AVERAGE(R16:S16) -> 26.5 | V16: 9 | W16: =GI!$H$10 -> Danait Alem Haile | X16: =GI!$I$10 -> F | Y16: =$R$18 -> 56 | Z16: =$R$152 -> 60 | AA16: =$R$285 -> 56 | AB16: =$R$352 -> 58 | AC16: =$R$419 -> 39 | AD16: =$R$553 -> 78 | AE16: =$R$687 -> 70 | AF16: =$R$754 -> 0 | AG16: =SUM(Y16:AE16) -> 417 | AH16: =AG16/7 -> 59.571429 | AI16: =RANK(AH16, _1Q_AVERAGE) -> 41 | AJ16: =IF(AH16>=GI!$B$64, "PRO", "DET") -> PRO | AL16: =UPPER(GI!$B$11) -> HISTORY | AM16: =COUNTIFS(_1Q_COL_5, $BA$6, _1Q_COL_5, $BC$6, _1Q_SEX, "M") -> 0 | AN16: =COUNTIFS(_1Q_COL_5, $BA$6, _1Q_COL_5, $BC$6, _1Q_SEX, "F") -> 0 | AO16: =SUM(AM16:AN16) -> 0 | AP16: =COUNTIFS(_1Q_COL_5, $BA$7, _1Q_COL_5, $BC$7, _1Q_SEX, "M") -> 13 | AQ16: =COUNTIFS(_1Q_COL_5, $BA$7, _1Q_COL_5, $BC$7, _1Q_SEX, "F") -> 7 | AR16: =SUM(AP16:AQ16) -> 20 | AS16: =COUNTIFS(_1Q_COL_5, $BA$8, _1Q_COL_5, $BC$8, _1Q_SEX, "M") -> 8 | AT16: =COUNTIFS(_1Q_COL_5, $BA$8, _1Q_COL_5, $BC$8, _1Q_SEX, "F") -> 5 | AU16: =SUM(AS16:AT16) -> 13 | AV16: =COUNTIFS(_1Q_COL_5, $BA$9, _1Q_COL_5, $BC$9, _1Q_SEX, "M") -> 5 | AW16: =COUNTIFS(_1Q_COL_5, $BA$9, _1Q_COL_5, $BC$9, _1Q_SEX, "F") -> 5 | AX16: =SUM(AV16:AW16) -> 10 | AY16: =SUM(AO16,AR16,AU16,AX16) -> 43
A17: 8 | B17: =GI!$H$9 -> Dagim Hagos Mehari | E17: 66 | F17: =IF(E17>100,"SKURRR~!!", IF(A17>GI!$M$2," ", IF($D$6="-", " ", IF(ISBLANK(E17),"FALSE","")))) | I17: 8 | J17: =GI!$H$9 -> Dagim Hagos Mehari | N17: =IF(M17>100,"SKURRR~!!", IF(I17>GI!$M$2," ", IF($L$6="-", " ", IF(ISBLANK(M17),"FALSE","")))) -> FALSE | R17: =E17 -> 66 | S17: =M17 -> 0 | T17: =AVERAGE(R17:S17) -> 33 | V17: 10 | W17: =GI!$H$11 -> Daniel Alem Beyene | X17: =GI!$I$11 -> M | Y17: =$R$19 -> 74 | Z17: =$R$153 -> 61 | AA17: =$R$286 -> 67 | AB17: =$R$353 -> 81 | AC17: =$R$420 -> 73 | AD17: =$R$554 -> 73 | AE17: =$R$688 -> 74 | AF17: =$R$755 -> 0 | AG17: =SUM(Y17:AE17) -> 503 | AH17: =AG17/7 -> 71.857143 | AI17: =RANK(AH17, _1Q_AVERAGE) -> 19 | AJ17: =IF(AH17>=GI!$B$64, "PRO", "DET") -> PRO | AL17: PERCENTAG: | AM17: =AM16*100/$AU$5 -> 0 | AN17: =AN16*100/$AW$5 -> 0 | AO17: =AO16*100/$AY$5 -> 0 | AP17: =AP16*100/$AU$5 -> 50 | AQ17: =AQ16*100/$AW$5 -> 41.176471 | AR17: =AR16*100/$AY$5 -> 46.511628 | AS17: =AS16*100/$AU$5 -> 30.769231 | AT17: =AT16*100/$AW$5 -> 29.411765 | AU17: =AU16*100/$AY$5 -> 30.232558 | AV17: =AV16*100/$AU$5 -> 19.230769 | AW17: =AW16*100/$AW$5 -> 29.411765 | AX17: =AX16*100/$AY$5 -> 23.255814 | AY17: =SUM(AO17,AR17,AU17,AX17) -> 100
A18: 9 | B18: =GI!$H$10 -> Danait Alem Haile | E18: 56 | F18: =IF(E18>100,"SKURRR~!!", IF(A18>GI!$M$2," ", IF($D$6="-", " ", IF(ISBLANK(E18),"FALSE","")))) | I18: 9 | J18: =GI!$H$10 -> Danait Alem Haile | N18: =IF(M18>100,"SKURRR~!!", IF(I18>GI!$M$2," ", IF($L$6="-", " ", IF(ISBLANK(M18),"FALSE","")))) -> FALSE | R18: =E18 -> 56 | S18: =M18 -> 0 | T18: =AVERAGE(R18:S18) -> 28 | V18: 11 | W18: =GI!$H$12 -> Dawit Gebegziabher Teklay | X18: =GI!$I$12 -> M | Y18: =$R$20 -> 63 | Z18: =$R$154 -> 60 | AA18: =$R$287 -> 76 | AB18: =$R$354 -> 59 | AC18: =$R$421 -> 60 | AD18: =$R$555 -> 74 | AE18: =$R$689 -> 66 | AF18: =$R$756 -> 0 | AG18: =SUM(Y18:AE18) -> 458 | AH18: =AG18/7 -> 65.428571 | AI18: =RANK(AH18, _1Q_AVERAGE) -> 35 | AJ18: =IF(AH18>=GI!$B$64, "PRO", "DET") -> PRO | AL18: =UPPER(GI!$B$12) -> GEOGRAPHY | AM18: =COUNTIFS(_1Q_COL_6, $BA$6, _1Q_COL_6, $BC$6, _1Q_SEX, "M") -> 0 | AN18: =COUNTIFS(_1Q_COL_6, $BA$6, _1Q_COL_6, $BC$6, _1Q_SEX, "F") -> 2 | AO18: =SUM(AM18:AN18) -> 2 | AP18: =COUNTIFS(_1Q_COL_6, $BA$7, _1Q_COL_6, $BC$7, _1Q_SEX, "M") -> 16 | AQ18: =COUNTIFS(_1Q_COL_6, $BA$7, _1Q_COL_6, $BC$7, _1Q_SEX, "F") -> 6 | AR18: =SUM(AP18:AQ18) -> 22 | AS18: =COUNTIFS(_1Q_COL_6, $BA$8, _1Q_COL_6, $BC$8, _1Q_SEX, "M") -> 7 | AT18: =COUNTIFS(_1Q_COL_6, $BA$8, _1Q_COL_6, $BC$8, _1Q_SEX, "F") -> 5 | AU18: =SUM(AS18:AT18) -> 12 | AV18: =COUNTIFS(_1Q_COL_6, $BA$9, _1Q_COL_6, $BC$9, _1Q_SEX, "M") -> 3 | AW18: =COUNTIFS(_1Q_COL_6, $BA$9, _1Q_COL_6, $BC$9, _1Q_SEX, "F") -> 4 | AX18: =SUM(AV18:AW18) -> 7 | AY18: =SUM(AO18,AR18,AU18,AX18) -> 43
A19: 10 | B19: =GI!$H$11 -> Daniel Alem Beyene | E19: 74 | F19: =IF(E19>100,"SKURRR~!!", IF(A19>GI!$M$2," ", IF($D$6="-", " ", IF(ISBLANK(E19),"FALSE","")))) | I19: 10 | J19: =GI!$H$11 -> Daniel Alem Beyene | N19: =IF(M19>100,"SKURRR~!!", IF(I19>GI!$M$2," ", IF($L$6="-", " ", IF(ISBLANK(M19),"FALSE","")))) -> FALSE | R19: =E19 -> 74 | S19: =M19 -> 0 | T19: =AVERAGE(R19:S19) -> 37 | V19: 12 | W19: =GI!$H$13 -> Ibrahim Ahmedin Ebrahim | X19: =GI!$I$13 -> M | Y19: =$R$21 -> 74 | Z19: =$R$155 -> 57 | AA19: =$R$288 -> 86 | AB19: =$R$355 -> 85 | AC19: =$R$422 -> 74 | AD19: =$R$556 -> 92 | AE19: =$R$690 -> 81 | AF19: =$R$757 -> 0 | AG19: =SUM(Y19:AE19) -> 549 | AH19: =AG19/7 -> 78.428571 | AI19: =RANK(AH19, _1Q_AVERAGE) -> 8 | AJ19: =IF(AH19>=GI!$B$64, "PRO", "DET") -> PRO | AL19: PERCENTAG: | AM19: =AM18*100/$AU$5 -> 0 | AN19: =AN18*100/$AW$5 -> 11.764706 | AO19: =AO18*100/$AY$5 -> 4.6511628 | AP19: =AP18*100/$AU$5 -> 61.538462 | AQ19: =AQ18*100/$AW$5 -> 35.294118 | AR19: =AR18*100/$AY$5 -> 51.162791 | AS19: =AS18*100/$AU$5 -> 26.923077 | AT19: =AT18*100/$AW$5 -> 29.411765 | AU19: =AU18*100/$AY$5 -> 27.906977 | AV19: =AV18*100/$AU$5 -> 11.538462 | AW19: =AW18*100/$AW$5 -> 23.529412 | AX19: =AX18*100/$AY$5 -> 16.27907 | AY19: =SUM(AO19,AR19,AU19,AX19) -> 100
A20: 11 | B20: =GI!$H$12 -> Dawit Gebegziabher Teklay | E20: 63 | F20: =IF(E20>100,"SKURRR~!!", IF(A20>GI!$M$2," ", IF($D$6="-", " ", IF(ISBLANK(E20),"FALSE","")))) | I20: 11 | J20: =GI!$H$12 -> Dawit Gebegziabher Teklay | N20: =IF(M20>100,"SKURRR~!!", IF(I20>GI!$M$2," ", IF($L$6="-", " ", IF(ISBLANK(M20),"FALSE","")))) -> FALSE | R20: =E20 -> 63 | S20: =M20 -> 0 | T20: =AVERAGE(R20:S20) -> 31.5 | V20: 13 | W20: =GI!$H$14 -> Eldana Tewelde Negash | X20: =GI!$I$14 -> F | Y20: =$R$22 -> 61 | Z20: =$R$156 -> 62 | AA20: =$R$289 -> 81 | AB20: =$R$356 -> 83 | AC20: =$R$423 -> 72 | AD20: =$R$557 -> 75 | AE20: =$R$691 -> 74 | AF20: =$R$758 -> 0 | AG20: =SUM(Y20:AE20) -> 508 | AH20: =AG20/7 -> 72.571429 | AI20: =RANK(AH20, _1Q_AVERAGE) -> 18 | AJ20: =IF(AH20>=GI!$B$64, "PRO", "DET") -> PRO | AL20: =UPPER(GI!$B$13) -> ECONOMICS | AM20: =COUNTIFS(_1Q_COL_7, $BA$6, _1Q_COL_7, $BC$6, _1Q_SEX, "M") -> 1 | AN20: =COUNTIFS(_1Q_COL_7, $BA$6, _1Q_COL_7, $BC$6, _1Q_SEX, "F") -> 3 | AO20: =SUM(AM20:AN20) -> 4 | AP20: =COUNTIFS(_1Q_COL_7, $BA$7, _1Q_COL_7, $BC$7, _1Q_SEX, "M") -> 22 | AQ20: =COUNTIFS(_1Q_COL_7, $BA$7, _1Q_COL_7, $BC$7, _1Q_SEX, "F") -> 9 | AR20: =SUM(AP20:AQ20) -> 31 | AS20: =COUNTIFS(_1Q_COL_7, $BA$8, _1Q_COL_7, $BC$8, _1Q_SEX, "M") -> 2 | AT20: =COUNTIFS(_1Q_COL_7, $BA$8, _1Q_COL_7, $BC$8, _1Q_SEX, "F") -> 4 | AU20: =SUM(AS20:AT20) -> 6 | AV20: =COUNTIFS(_1Q_COL_7, $BA$9, _1Q_COL_7, $BC$9, _1Q_SEX, "M") -> 1 | AW20: =COUNTIFS(_1Q_COL_7, $BA$9, _1Q_COL_7, $BC$9, _1Q_SEX, "F") -> 1 | AX20: =SUM(AV20:AW20) -> 2 | AY20: =SUM(AO20,AR20,AU20,AX20) -> 43
A21: 12 | B21: =GI!$H$13 -> Ibrahim Ahmedin Ebrahim | E21: 74 | F21: =IF(E21>100,"SKURRR~!!", IF(A21>GI!$M$2," ", IF($D$6="-", " ", IF(ISBLANK(E21),"FALSE","")))) | I21: 12 | J21: =GI!$H$13 -> Ibrahim Ahmedin Ebrahim | N21: =IF(M21>100,"SKURRR~!!", IF(I21>GI!$M$2," ", IF($L$6="-", " ", IF(ISBLANK(M21),"FALSE","")))) -> FALSE | R21: =E21 -> 74 | S21: =M21 -> 0 | T21: =AVERAGE(R21:S21) -> 37 | V21: 14 | W21: =GI!$H$15 -> Elilta Asay Eyasu | X21: =GI!$I$15 -> F | Y21: =$R$23 -> 75 | Z21: =$R$157 -> 52 | AA21: =$R$290 -> 90 | AB21: =$R$357 -> 82 | AC21: =$R$424 -> 79 | AD21: =$R$558 -> 91 | AE21: =$R$692 -> 88 | AF21: =$R$759 -> 0 | AG21: =SUM(Y21:AE21) -> 557 | AH21: =AG21/7 -> 79.571429 | AI21: =RANK(AH21, _1Q_AVERAGE) -> 6 | AJ21: =IF(AH21>=GI!$B$64, "PRO", "DET") -> PRO | AL21: PERCENTAG: | AM21: =AM20*100/$AU$5 -> 3.8461538 | AN21: =AN20*100/$AW$5 -> 17.647059 | AO21: =AO20*100/$AY$5 -> 9.3023256 | AP21: =AP20*100/$AU$5 -> 84.615385 | AQ21: =AQ20*100/$AW$5 -> 52.941176 | AR21: =AR20*100/$AY$5 -> 72.093023 | AS21: =AS20*100/$AU$5 -> 7.6923077 | AT21: =AT20*100/$AW$5 -> 23.529412 | AU21: =AU20*100/$AY$5 -> 13.953488 | AV21: =AV20*100/$AU$5 -> 3.8461538 | AW21: =AW20*100/$AW$5 -> 5.8823529 | AX21: =AX20*100/$AY$5 -> 4.6511628 | AY21: =SUM(AO21,AR21,AU21,AX21) -> 100
A22: 13 | B22: =GI!$H$14 -> Eldana Tewelde Negash | E22: 61 | F22: =IF(E22>100,"SKURRR~!!", IF(A22>GI!$M$2," ", IF($D$6="-", " ", IF(ISBLANK(E22),"FALSE","")))) | I22: 13 | J22: =GI!$H$14 -> Eldana Tewelde Negash | N22: =IF(M22>100,"SKURRR~!!", IF(I22>GI!$M$2," ", IF($L$6="-", " ", IF(ISBLANK(M22),"FALSE","")))) -> FALSE | R22: =E22 -> 61 | S22: =M22 -> 0 | T22: =AVERAGE(R22:S22) -> 30.5 | V22: 15 | W22: =GI!$H$16 -> Emebet Haftay Gebremichael | X22: =GI!$I$16 -> F | Y22: =$R$24 -> 76 | Z22: =$R$158 -> 61 | AA22: =$R$291 -> 100 | AB22: =$R$358 -> 96 | AC22: =$R$425 -> 88 | AD22: =$R$559 -> 89 | AE22: =$R$693 -> 94 | AF22: =$R$760 -> 0 | AG22: =SUM(Y22:AE22) -> 604 | AH22: =AG22/7 -> 86.285714 | AI22: =RANK(AH22, _1Q_AVERAGE) -> 3 | AJ22: =IF(AH22>=GI!$B$64, "PRO", "DET") -> PRO | AL22: =UPPER(GI!$B$14) -> -
A23: 14 | B23: =GI!$H$15 -> Elilta Asay Eyasu | E23: 75 | F23: =IF(E23>100,"SKURRR~!!", IF(A23>GI!$M$2," ", IF($D$6="-", " ", IF(ISBLANK(E23),"FALSE","")))) | I23: 14 | J23: =GI!$H$15 -> Elilta Asay Eyasu | N23: =IF(M23>100,"SKURRR~!!", IF(I23>GI!$M$2," ", IF($L$6="-", " ", IF(ISBLANK(M23),"FALSE","")))) -> FALSE | R23: =E23 -> 75 | S23: =M23 -> 0 | T23: =AVERAGE(R23:S23) -> 37.5 | V23: 16 | W23: =GI!$H$17 -> Ermiyas Gebremeskel Hailu | X23: =GI!$I$17 -> M | Y23: =$R$25 -> 59 | Z23: =$R$159 -> 60 | AA23: =$R$292 -> 70 | AB23: =$R$359 -> 76 | AC23: =$R$426 -> 62 | AD23: =$R$560 -> 90 | AE23: =$R$694 -> 63 | AF23: =$R$761 -> 0 | AG23: =SUM(Y23:AE23) -> 480 | AH23: =AG23/7 -> 68.571429 | AI23: =RANK(AH23, _1Q_AVERAGE) -> 27 | AJ23: =IF(AH23>=GI!$B$64, "PRO", "DET") -> PRO | AL23: PERCENTAG:
A24: 15 | B24: =GI!$H$16 -> Emebet Haftay Gebremichael | E24: 76 | F24: =IF(E24>100,"SKURRR~!!", IF(A24>GI!$M$2," ", IF($D$6="-", " ", IF(ISBLANK(E24),"FALSE","")))) | I24: 15 | J24: =GI!$H$16 -> Emebet Haftay Gebremichael | N24: =IF(M24>100,"SKURRR~!!", IF(I24>GI!$M$2," ", IF($L$6="-", " ", IF(ISBLANK(M24),"FALSE","")))) -> FALSE | R24: =E24 -> 76 | S24: =M24 -> 0 | T24: =AVERAGE(R24:S24) -> 38 | V24: 17 | W24: =GI!$H$18 -> Esrom Amanuel Tsegay | X24: =GI!$I$18 -> M | Y24: =$R$26 -> 62 | Z24: =$R$160 -> 65 | AA24: =$R$293 -> 92 | AB24: =$R$360 -> 84 | AC24: =$R$427 -> 81 | AD24: =$R$561 -> 93 | AE24: =$R$695 -> 91 | AF24: =$R$762 -> 0 | AG24: =SUM(Y24:AE24) -> 568 | AH24: =AG24/7 -> 81.142857 | AI24: =RANK(AH24, _1Q_AVERAGE) -> 4 | AJ24: =IF(AH24>=GI!$B$64, "PRO", "DET") -> PRO | AL24: =UPPER(GI!$B$15) -> ICT | AM24: =COUNTIFS(_1Q_COL_9, $BA$6, _1Q_COL_9, $BC$6, _1Q_SEX, "M") -> 0 | AN24: =COUNTIFS(_1Q_COL_9, $BA$6, _1Q_COL_9, $BC$6, _1Q_SEX, "F") -> 0 | AO24: =SUM(AM24:AN24) -> 0 | AP24: =COUNTIFS(_1Q_COL_9, $BA$7, _1Q_COL_9, $BC$7, _1Q_SEX, "M") -> 5 | AQ24: =COUNTIFS(_1Q_COL_9, $BA$7, _1Q_COL_9, $BC$7, _1Q_SEX, "F") -> 2 | AR24: =SUM(AP24:AQ24) -> 7 | AS24: =COUNTIFS(_1Q_COL_9, $BA$8, _1Q_COL_9, $BC$8, _1Q_SEX, "M") -> 8 | AT24: =COUNTIFS(_1Q_COL_9, $BA$8, _1Q_COL_9, $BC$8, _1Q_SEX, "F") -> 6 | AU24: =SUM(AS24:AT24) -> 14 | AV24: =COUNTIFS(_1Q_COL_9, $BA$9, _1Q_COL_9, $BC$9, _1Q_SEX, "M") -> 13 | AW24: =COUNTIFS(_1Q_COL_9, $BA$9, _1Q_COL_9, $BC$9, _1Q_SEX, "F") -> 9 | AX24: =SUM(AV24:AW24) -> 22 | AY24: =SUM(AO24,AR24,AU24,AX24) -> 43
A25: 16 | B25: =GI!$H$17 -> Ermiyas Gebremeskel Hailu | E25: 59 | F25: =IF(E25>100,"SKURRR~!!", IF(A25>GI!$M$2," ", IF($D$6="-", " ", IF(ISBLANK(E25),"FALSE","")))) | I25: 16 | J25: =GI!$H$17 -> Ermiyas Gebremeskel Hailu | N25: =IF(M25>100,"SKURRR~!!", IF(I25>GI!$M$2," ", IF($L$6="-", " ", IF(ISBLANK(M25),"FALSE","")))) -> FALSE | R25: =E25 -> 59 | S25: =M25 -> 0 | T25: =AVERAGE(R25:S25) -> 29.5 | V25: 18 | W25: =GI!$H$19 -> Eyorsalem Afera Gebremedhin | X25: =GI!$I$19 -> F | Y25: =$R$27 -> 83 | Z25: =$R$161 -> 83 | AA25: =$R$294 -> 97 | AB25: =$R$361 -> 91 | AC25: =$R$428 -> 76 | AD25: =$R$562 -> 95 | AE25: =$R$696 -> 98 | AF25: =$R$763 -> 0 | AG25: =SUM(Y25:AE25) -> 623 | AH25: =AG25/7 -> 89 | AI25: =RANK(AH25, _1Q_AVERAGE) -> 2 | AJ25: =IF(AH25>=GI!$B$64, "PRO", "DET") -> PRO | AL25: PERCENTAG: | AM25: =AM24*100/$AU$5 -> 0 | AN25: =AN24*100/$AW$5 -> 0 | AO25: =AO24*100/$AY$5 -> 0 | AP25: =AP24*100/$AU$5 -> 19.230769 | AQ25: =AQ24*100/$AW$5 -> 11.764706 | AR25: =AR24*100/$AY$5 -> 16.27907 | AS25: =AS24*100/$AU$5 -> 30.769231 | AT25: =AT24*100/$AW$5 -> 35.294118 | AU25: =AU24*100/$AY$5 -> 32.55814 | AV25: =AV24*100/$AU$5 -> 50 | AW25: =AW24*100/$AW$5 -> 52.941176 | AX25: =AX24*100/$AY$5 -> 51.162791 | AY25: =SUM(AO25,AR25,AU25,AX25) -> 100
A26: 17 | B26: =GI!$H$18 -> Esrom Amanuel Tsegay | E26: 62 | F26: =IF(E26>100,"SKURRR~!!", IF(A26>GI!$M$2," ", IF($D$6="-", " ", IF(ISBLANK(E26),"FALSE","")))) | I26: 17 | J26: =GI!$H$18 -> Esrom Amanuel Tsegay | N26: =IF(M26>100,"SKURRR~!!", IF(I26>GI!$M$2," ", IF($L$6="-", " ", IF(ISBLANK(M26),"FALSE","")))) -> FALSE | R26: =E26 -> 62 | S26: =M26 -> 0 | T26: =AVERAGE(R26:S26) -> 31 | V26: 19 | W26: =GI!$H$20 -> Fasil Alem Kahsay | X26: =GI!$I$20 -> M | Y26: =$R$28 -> 62 | Z26: =$R$162 -> 55 | AA26: =$R$295 -> 80 | AB26: =$R$362 -> 63 | AC26: =$R$429 -> 56 | AD26: =$R$563 -> 65 | AE26: =$R$697 -> 75 | AF26: =$R$764 -> 0 | AG26: =SUM(Y26:AE26) -> 456 | AH26: =AG26/7 -> 65.142857 | AI26: =RANK(AH26, _1Q_AVERAGE) -> 36 | AJ26: =IF(AH26>=GI!$B$64, "PRO", "DET") -> PRO | AL26: =UPPER(GI!$B$16) -> -
A27: 18 | B27: =GI!$H$19 -> Eyorsalem Afera Gebremedhin | E27: 83 | F27: =IF(E27>100,"SKURRR~!!", IF(A27>GI!$M$2," ", IF($D$6="-", " ", IF(ISBLANK(E27),"FALSE","")))) | I27: 18 | J27: =GI!$H$19 -> Eyorsalem Afera Gebremedhin | N27: =IF(M27>100,"SKURRR~!!", IF(I27>GI!$M$2," ", IF($L$6="-", " ", IF(ISBLANK(M27),"FALSE","")))) -> FALSE | R27: =E27 -> 83 | S27: =M27 -> 0 | T27: =AVERAGE(R27:S27) -> 41.5 | V27: 20 | W27: =GI!$H$21 -> Hassen Abdelruhman Salih | X27: =GI!$I$21 -> M | Y27: =$R$29 -> 68 | Z27: =$R$163 -> 64 | AA27: =$R$296 -> 75 | AB27: =$R$363 -> 76 | AC27: =$R$430 -> 64 | AD27: =$R$564 -> 95 | AE27: =$R$698 -> 78 | AF27: =$R$765 -> 0 | AG27: =SUM(Y27:AE27) -> 520 | AH27: =AG27/7 -> 74.285714 | AI27: =RANK(AH27, _1Q_AVERAGE) -> 16 | AJ27: =IF(AH27>=GI!$B$64, "PRO", "DET") -> PRO | AL27: PERCENTAG:
A28: 19 | B28: =GI!$H$20 -> Fasil Alem Kahsay | E28: 62 | F28: =IF(E28>100,"SKURRR~!!", IF(A28>GI!$M$2," ", IF($D$6="-", " ", IF(ISBLANK(E28),"FALSE","")))) | I28: 19 | J28: =GI!$H$20 -> Fasil Alem Kahsay | N28: =IF(M28>100,"SKURRR~!!", IF(I28>GI!$M$2," ", IF($L$6="-", " ", IF(ISBLANK(M28),"FALSE","")))) -> FALSE | R28: =E28 -> 62 | S28: =M28 -> 0 | T28: =AVERAGE(R28:S28) -> 31 | V28: 21 | W28: =GI!$H$22 -> Heldana Mengstu Mebrahtu | X28: =GI!$I$22 -> F | Y28: =$R$30 -> 76 | Z28: =$R$164 -> 60 | AA28: =$R$297 -> 84 | AB28: =$R$364 -> 87 | AC28: =$R$431 -> 73 | AD28: =$R$565 -> 82 | AE28: =$R$699 -> 82 | AF28: =$R$766 -> 0 | AG28: =SUM(Y28:AE28) -> 544 | AH28: =AG28/7 -> 77.714286 | AI28: =RANK(AH28, _1Q_AVERAGE) -> 10 | AJ28: =IF(AH28>=GI!$B$64, "PRO", "DET") -> PRO | AL28: =UPPER(GI!$B$17) -> ACCOUNTING AND FINANCE | AM28: =COUNTIFS(_1Q_COL_11, $BA$6, _1Q_COL_11, $BC$6, _1Q_SEX, "M") -> 0 | AN28: =COUNTIFS(_1Q_COL_11, $BA$6, _1Q_COL_11, $BC$6, _1Q_SEX, "F") -> 0 | AO28: =SUM(AM28:AN28) -> 0 | AP28: =COUNTIFS(_1Q_COL_11, $BA$7, _1Q_COL_11, $BC$7, _1Q_SEX, "M") -> 12 | AQ28: =COUNTIFS(_1Q_COL_11, $BA$7, _1Q_COL_11, $BC$7, _1Q_SEX, "F") -> 5 | AR28: =SUM(AP28:AQ28) -> 17 | AS28: =COUNTIFS(_1Q_COL_11, $BA$8, _1Q_COL_11, $BC$8, _1Q_SEX, "M") -> 11 | AT28: =COUNTIFS(_1Q_COL_11, $BA$8, _1Q_COL_11, $BC$8, _1Q_SEX, "F") -> 8 | AU28: =SUM(AS28:AT28) -> 19 | AV28: =COUNTIFS(_1Q_COL_11, $BA$9, _1Q_COL_11, $BC$9, _1Q_SEX, "M") -> 3 | AW28: =COUNTIFS(_1Q_COL_11, $BA$9, _1Q_COL_11, $BC$9, _1Q_SEX, "F") -> 4 | AX28: =SUM(AV28:AW28) -> 7 | AY28: =SUM(AO28,AR28,AU28,AX28) -> 43
A29: 20 | B29: =GI!$H$21 -> Hassen Abdelruhman Salih | E29: 68 | F29: =IF(E29>100,"SKURRR~!!", IF(A29>GI!$M$2," ", IF($D$6="-", " ", IF(ISBLANK(E29),"FALSE","")))) | I29: 20 | J29: =GI!$H$21 -> Hassen Abdelruhman Salih | N29: =IF(M29>100,"SKURRR~!!", IF(I29>GI!$M$2," ", IF($L$6="-", " ", IF(ISBLANK(M29),"FALSE","")))) -> FALSE | R29: =E29 -> 68 | S29: =M29 -> 0 | T29: =AVERAGE(R29:S29) -> 34 | V29: 22 | W29: =GI!$H$23 -> Hilina Aregawi Abrha | X29: =GI!$I$23 -> F | Y29: =$R$31 -> 61 | Z29: =$R$165 -> 54 | AA29: =$R$298 -> 94 | AB29: =$R$365 -> 80 | AC29: =$R$432 -> 72 | AD29: =$R$566 -> 84 | AE29: =$R$700 -> 88 | AF29: =$R$767 -> 0 | AG29: =SUM(Y29:AE29) -> 533 | AH29: =AG29/7 -> 76.142857 | AI29: =RANK(AH29, _1Q_AVERAGE) -> 12 | AJ29: =IF(AH29>=GI!$B$64, "PRO", "DET") -> PRO | AL29: PERCENTAG: | AM29: =AM28*100/$AU$5 -> 0 | AN29: =AN28*100/$AW$5 -> 0 | AO29: =AO28*100/$AY$5 -> 0 | AP29: =AP28*100/$AU$5 -> 46.153846 | AQ29: =AQ28*100/$AW$5 -> 29.411765 | AR29: =AR28*100/$AY$5 -> 39.534884 | AS29: =AS28*100/$AU$5 -> 42.307692 | AT29: =AT28*100/$AW$5 -> 47.058824 | AU29: =AU28*100/$AY$5 -> 44.186047 | AV29: =AV28*100/$AU$5 -> 11.538462 | AW29: =AW28*100/$AW$5 -> 23.529412 | AX29: =AX28*100/$AY$5 -> 16.27907 | AY29: =SUM(AO29,AR29,AU29,AX29) -> 100
A30: 21 | B30: =GI!$H$22 -> Heldana Mengstu Mebrahtu | E30: 76 | F30: =IF(E30>100,"SKURRR~!!", IF(A30>GI!$M$2," ", IF($D$6="-", " ", IF(ISBLANK(E30),"FALSE","")))) | I30: 21 | J30: =GI!$H$22 -> Heldana Mengstu Mebrahtu | N30: =IF(M30>100,"SKURRR~!!", IF(I30>GI!$M$2," ", IF($L$6="-", " ", IF(ISBLANK(M30),"FALSE","")))) -> FALSE | R30: =E30 -> 76 | S30: =M30 -> 0 | T30: =AVERAGE(R30:S30) -> 38 | V30: 23 | W30: =GI!$H$24 -> Kaleab Haile Kahsay | X30: =GI!$I$24 -> M | Y30: =$R$32 -> 74 | Z30: =$R$166 -> 53 | AA30: =$R$299 -> 82 | AB30: =$R$366 -> 78 | AC30: =$R$433 -> 73 | AD30: =$R$567 -> 84 | AE30: =$R$701 -> 78 | AF30: =$R$768 -> 0 | AG30: =SUM(Y30:AE30) -> 522 | AH30: =AG30/7 -> 74.571429 | AI30: =RANK(AH30, _1Q_AVERAGE) -> 14 | AJ30: =IF(AH30>=GI!$B$64, "PRO", "DET") -> PRO | AL30: =UPPER(GI!$B$18) -> - | AM30: =COUNTIFS(_1Q_COL_12, $BA$6, _1Q_COL_12, $BC$6, _1Q_SEX, "M") -> 0 | AN30: =COUNTIFS(_1Q_COL_12, $BA$6, _1Q_COL_12, $BC$6, _1Q_SEX, "F") -> 0 | AO30: =SUM(AM30:AN30) -> 0 | AP30: =COUNTIFS(_1Q_COL_12, $BA$7, _1Q_COL_12, $BC$7, _1Q_SEX, "M") -> 0 | AQ30: =COUNTIFS(_1Q_COL_12, $BA$7, _1Q_COL_12, $BC$7, _1Q_SEX, "F") -> 0 | AR30: =SUM(AP30:AQ30) -> 0 | AS30: =COUNTIFS(_1Q_COL_12, $BA$8, _1Q_COL_12, $BC$8, _1Q_SEX, "M") -> 0 | AT30: =COUNTIFS(_1Q_COL_12, $BA$8, _1Q_COL_12, $BC$8, _1Q_SEX, "F") -> 0 | AU30: =SUM(AS30:AT30) -> 0 | AV30: =COUNTIFS(_1Q_COL_12, $BA$9, _1Q_COL_12, $BC$9, _1Q_SEX, "M") -> 0 | AW30: =COUNTIFS(_1Q_COL_12, $BA$9, _1Q_COL_12, $BC$9, _1Q_SEX, "F") -> 0 | AX30: =SUM(AV30:AW30) -> 0 | AY30: =SUM(AO30,AR30,AU30,AX30) -> 0
A31: 22 | B31: =GI!$H$23 -> Hilina Aregawi Abrha | E31: 61 | F31: =IF(E31>100,"SKURRR~!!", IF(A31>GI!$M$2," ", IF($D$6="-", " ", IF(ISBLANK(E31),"FALSE","")))) | I31: 22 | J31: =GI!$H$23 -> Hilina Aregawi Abrha | N31: =IF(M31>100,"SKURRR~!!", IF(I31>GI!$M$2," ", IF($L$6="-", " ", IF(ISBLANK(M31),"FALSE","")))) -> FALSE | R31: =E31 -> 61 | S31: =M31 -> 0 | T31: =AVERAGE(R31:S31) -> 30.5 | V31: 24 | W31: =GI!$H$25 -> Kalkidan Haile Berhe | X31: =GI!$I$25 -> F | Y31: =$R$33 -> 71 | Z31: =$R$167 -> 51 | AA31: =$R$300 -> 55 | AB31: =$R$367 -> 51 | AC31: =$R$434 -> 58 | AD31: =$R$568 -> 82 | AE31: =$R$702 -> 71 | AF31: =$R$769 -> 0 | AG31: =SUM(Y31:AE31) -> 439 | AH31: =AG31/7 -> 62.714286 | AI31: =RANK(AH31, _1Q_AVERAGE) -> 38 | AJ31: =IF(AH31>=GI!$B$64, "PRO", "DET") -> PRO | AL31: PERCENTAG: | AM31: =AM30*100/$AU$5 -> 0 | AN31: =AN30*100/$AW$5 -> 0 | AO31: =AO30*100/$AY$5 -> 0 | AP31: =AP30*100/$AU$5 -> 0 | AQ31: =AQ30*100/$AW$5 -> 0 | AR31: =AR30*100/$AY$5 -> 0 | AS31: =AS30*100/$AU$5 -> 0 | AT31: =AT30*100/$AW$5 -> 0 | AU31: =AU30*100/$AY$5 -> 0 | AV31: =AV30*100/$AU$5 -> 0 | AW31: =AW30*100/$AW$5 -> 0 | AX31: =AX30*100/$AY$5 -> 0 | AY31: =SUM(AO31,AR31,AU31,AX31) -> 0
A32: 23 | B32: =GI!$H$24 -> Kaleab Haile Kahsay | E32: 74 | F32: =IF(E32>100,"SKURRR~!!", IF(A32>GI!$M$2," ", IF($D$6="-", " ", IF(ISBLANK(E32),"FALSE","")))) | I32: 23 | J32: =GI!$H$24 -> Kaleab Haile Kahsay | N32: =IF(M32>100,"SKURRR~!!", IF(I32>GI!$M$2," ", IF($L$6="-", " ", IF(ISBLANK(M32),"FALSE","")))) -> FALSE | R32: =E32 -> 74 | S32: =M32 -> 0 | T32: =AVERAGE(R32:S32) -> 37 | V32: 25 | W32: =GI!$H$26 -> Kidus Tadesse Yewegalet | X32: =GI!$I$26 -> M | Y32: =$R$34 -> 59 | Z32: =$R$168 -> 60 | AA32: =$R$301 -> 74 | AB32: =$R$368 -> 72 | AC32: =$R$435 -> 53 | AD32: =$R$569 -> 82 | AE32: =$R$703 -> 76 | AF32: =$R$770 -> 0 | AG32: =SUM(Y32:AE32) -> 476 | AH32: =AG32/7 -> 68 | AI32: =RANK(AH32, _1Q_AVERAGE) -> 29 | AJ32: =IF(AH32>=GI!$B$64, "PRO", "DET") -> PRO
A33: 24 | B33: =GI!$H$25 -> Kalkidan Haile Berhe | E33: 71 | F33: =IF(E33>100,"SKURRR~!!", IF(A33>GI!$M$2," ", IF($D$6="-", " ", IF(ISBLANK(E33),"FALSE","")))) | I33: 24 | J33: =GI!$H$25 -> Kalkidan Haile Berhe | N33: =IF(M33>100,"SKURRR~!!", IF(I33>GI!$M$2," ", IF($L$6="-", " ", IF(ISBLANK(M33),"FALSE","")))) -> FALSE | R33: =E33 -> 71 | S33: =M33 -> 0 | T33: =AVERAGE(R33:S33) -> 35.5 | V33: 26 | W33: =GI!$H$27 -> Lidiya Mulu Gebreegzabher | X33: =GI!$I$27 -> F | Y33: =$R$35 -> 49 | Z33: =$R$169 -> 58 | AA33: =$R$302 -> 63 | AB33: =$R$369 -> 61 | AC33: =$R$436 -> 49 | AD33: =$R$570 -> 73 | AE33: =$R$704 -> 74 | AF33: =$R$771 -> 0 | AG33: =SUM(Y33:AE33) -> 427 | AH33: =AG33/7 -> 61 | AI33: =RANK(AH33, _1Q_AVERAGE) -> 40 | AJ33: =IF(AH33>=GI!$B$64, "PRO", "DET") -> PRO
A34: 25 | B34: =GI!$H$26 -> Kidus Tadesse Yewegalet | E34: 59 | F34: =IF(E34>100,"SKURRR~!!", IF(A34>GI!$M$2," ", IF($D$6="-", " ", IF(ISBLANK(E34),"FALSE","")))) | I34: 25 | J34: =GI!$H$26 -> Kidus Tadesse Yewegalet | N34: =IF(M34>100,"SKURRR~!!", IF(I34>GI!$M$2," ", IF($L$6="-", " ", IF(ISBLANK(M34),"FALSE","")))) -> FALSE | R34: =E34 -> 59 | S34: =M34 -> 0 | T34: =AVERAGE(R34:S34) -> 29.5 | V34: 27 | W34: =GI!$H$28 -> Menkem Solomon Yihdego | X34: =GI!$I$28 -> M | Y34: =$R$36 -> 48 | Z34: =$R$170 -> 60 | AA34: =$R$303 -> 69 | AB34: =$R$370 -> 71 | AC34: =$R$437 -> 72 | AD34: =$R$571 -> 86 | AE34: =$R$705 -> 63 | AF34: =$R$772 -> 0 | AG34: =SUM(Y34:AE34) -> 469 | AH34: =AG34/7 -> 67 | AI34: =RANK(AH34, _1Q_AVERAGE) -> 32 | AJ34: =IF(AH34>=GI!$B$64, "PRO", "DET") -> PRO | AL34: =CONCATENATE(GI!$B$54," : ","AVERAGE") -> 1st SEMESTER RESULT STATISTICS : AVERAGE
A35: 26 | B35: =GI!$H$27 -> Lidiya Mulu Gebreegzabher | E35: 49 | F35: =IF(E35>100,"SKURRR~!!", IF(A35>GI!$M$2," ", IF($D$6="-", " ", IF(ISBLANK(E35),"FALSE","")))) | I35: 26 | J35: =GI!$H$27 -> Lidiya Mulu Gebreegzabher | N35: =IF(M35>100,"SKURRR~!!", IF(I35>GI!$M$2," ", IF($L$6="-", " ", IF(ISBLANK(M35),"FALSE","")))) -> FALSE | R35: =E35 -> 49 | S35: =M35 -> 0 | T35: =AVERAGE(R35:S35) -> 24.5 | V35: 28 | W35: =GI!$H$29 -> Mewael Semere Tewelde | X35: =GI!$I$29 -> M | Y35: =$R$37 -> 77 | Z35: =$R$171 -> 57 | AA35: =$R$304 -> 80 | AB35: =$R$371 -> 71 | AC35: =$R$438 -> 65 | AD35: =$R$572 -> 88 | AE35: =$R$706 -> 73 | AF35: =$R$773 -> 0 | AG35: =SUM(Y35:AE35) -> 511 | AH35: =AG35/7 -> 73 | AI35: =RANK(AH35, _1Q_AVERAGE) -> 17 | AJ35: =IF(AH35>=GI!$B$64, "PRO", "DET") -> PRO
A36: 27 | B36: =GI!$H$28 -> Menkem Solomon Yihdego | E36: 48 | F36: =IF(E36>100,"SKURRR~!!", IF(A36>GI!$M$2," ", IF($D$6="-", " ", IF(ISBLANK(E36),"FALSE","")))) | I36: 27 | J36: =GI!$H$28 -> Menkem Solomon Yihdego | N36: =IF(M36>100,"SKURRR~!!", IF(I36>GI!$M$2," ", IF($L$6="-", " ", IF(ISBLANK(M36),"FALSE","")))) -> FALSE | R36: =E36 -> 48 | S36: =M36 -> 0 | T36: =AVERAGE(R36:S36) -> 24 | V36: 29 | W36: =GI!$H$30 -> Mikiyas Engida Mesfin | X36: =GI!$I$30 -> M | Y36: =$R$38 -> 62 | Z36: =$R$172 -> 63 | AA36: =$R$305 -> 70 | AB36: =$R$372 -> 69 | AC36: =$R$439 -> 57 | AD36: =$R$573 -> 85 | AE36: =$R$707 -> 68 | AF36: =$R$774 -> 0 | AG36: =SUM(Y36:AE36) -> 474 | AH36: =AG36/7 -> 67.714286 | AI36: =RANK(AH36, _1Q_AVERAGE) -> 30 | AJ36: =IF(AH36>=GI!$B$64, "PRO", "DET") -> PRO
A37: 28 | B37: =GI!$H$29 -> Mewael Semere Tewelde | E37: 77 | F37: =IF(E37>100,"SKURRR~!!", IF(A37>GI!$M$2," ", IF($D$6="-", " ", IF(ISBLANK(E37),"FALSE","")))) | I37: 28 | J37: =GI!$H$29 -> Mewael Semere Tewelde | N37: =IF(M37>100,"SKURRR~!!", IF(I37>GI!$M$2," ", IF($L$6="-", " ", IF(ISBLANK(M37),"FALSE","")))) -> FALSE | R37: =E37 -> 77 | S37: =M37 -> 0 | T37: =AVERAGE(R37:S37) -> 38.5 | V37: 30 | W37: =GI!$H$31 -> Nahom Gobezay Beyene | X37: =GI!$I$31 -> M | Y37: =$R$39 -> 85 | Z37: =$R$173 -> 90 | AA37: =$R$306 -> 98 | AB37: =$R$373 -> 96 | AC37: =$R$440 -> 91 | AD37: =$R$574 -> 97 | AE37: =$R$708 -> 86 | AF37: =$R$775 -> 0 | AG37: =SUM(Y37:AE37) -> 643 | AH37: =AG37/7 -> 91.857143 | AI37: =RANK(AH37, _1Q_AVERAGE) -> 1 | AJ37: =IF(AH37>=GI!$B$64, "PRO", "DET") -> PRO | AM37: =$BA$6 &" " & $BC$6 -> >=1 <55 | AP37: =$BA$7 &" " & $BC$7 -> >=55 <75 | AS37: =$BA$8 &" " & $BC$8 -> >=75 <85 | AV37: =$BA$9 &" " & $BC$9 -> >=85 <=100 | AY37: TOTAL
A38: 29 | B38: =GI!$H$30 -> Mikiyas Engida Mesfin | E38: 62 | F38: =IF(E38>100,"SKURRR~!!", IF(A38>GI!$M$2," ", IF($D$6="-", " ", IF(ISBLANK(E38),"FALSE","")))) | I38: 29 | J38: =GI!$H$30 -> Mikiyas Engida Mesfin | N38: =IF(M38>100,"SKURRR~!!", IF(I38>GI!$M$2," ", IF($L$6="-", " ", IF(ISBLANK(M38),"FALSE","")))) -> FALSE | R38: =E38 -> 62 | S38: =M38 -> 0 | T38: =AVERAGE(R38:S38) -> 31 | V38: 31 | W38: =GI!$H$32 -> Nebyu Dawit Tadesse | X38: =GI!$I$32 -> M | Y38: =$R$40 -> 84 | Z38: =$R$174 -> 61 | AA38: =$R$307 -> 92 | AB38: =$R$374 -> 84 | AC38: =$R$441 -> 77 | AD38: =$R$575 -> 93 | AE38: =$R$709 -> 72 | AF38: =$R$776 -> 0 | AG38: =SUM(Y38:AE38) -> 563 | AH38: =AG38/7 -> 80.428571 | AI38: =RANK(AH38, _1Q_AVERAGE) -> 5 | AJ38: =IF(AH38>=GI!$B$64, "PRO", "DET") -> PRO | AM38: M | AN38: F | AO38: T | AP38: M | AQ38: F | AR38: T | AS38: M | AT38: F | AU38: T | AV38: M | AW38: F | AX38: T
A39: 30 | B39: =GI!$H$31 -> Nahom Gobezay Beyene | E39: 85 | F39: =IF(E39>100,"SKURRR~!!", IF(A39>GI!$M$2," ", IF($D$6="-", " ", IF(ISBLANK(E39),"FALSE","")))) | I39: 30 | J39: =GI!$H$31 -> Nahom Gobezay Beyene | N39: =IF(M39>100,"SKURRR~!!", IF(I39>GI!$M$2," ", IF($L$6="-", " ", IF(ISBLANK(M39),"FALSE","")))) -> FALSE | R39: =E39 -> 85 | S39: =M39 -> 0 | T39: =AVERAGE(R39:S39) -> 42.5 | V39: 32 | W39: =GI!$H$33 -> Rahwa Luel Birhane | X39: =GI!$I$33 -> F | Y39: =$R$41 -> 70 | Z39: =$R$175 -> 65 | AA39: =$R$308 -> 81 | AB39: =$R$375 -> 94 | AC39: =$R$442 -> 78 | AD39: =$R$576 -> 88 | AE39: =$R$710 -> 79 | AF39: =$R$777 -> 0 | AG39: =SUM(Y39:AE39) -> 555 | AH39: =AG39/7 -> 79.285714 | AI39: =RANK(AH39, _1Q_AVERAGE) -> 7 | AJ39: =IF(AH39>=GI!$B$64, "PRO", "DET") -> PRO | AM39: =COUNTIFS(_1Q_AVERAGE, $BA$6, _1Q_AVERAGE, $BC$6, _1Q_SEX, "M") -> 0 | AN39: =COUNTIFS(_1Q_AVERAGE, $BA$6, _1Q_AVERAGE, $BC$6, _1Q_SEX, "F") -> 0 | AO39: =SUM(AM39:AN39) -> 0 | AP39: =COUNTIFS(_1Q_AVERAGE, $BA$7, _1Q_AVERAGE, $BC$7, _1Q_SEX, "M") -> 20 | AQ39: =COUNTIFS(_1Q_AVERAGE, $BA$7, _1Q_AVERAGE, $BC$7, _1Q_SEX, "F") -> 10 | AR39: =SUM(AP39:AQ39) -> 30 | AS39: =COUNTIFS(_1Q_AVERAGE, $BA$8, _1Q_AVERAGE, $BC$8, _1Q_SEX, "M") -> 5 | AT39: =COUNTIFS(_1Q_AVERAGE, $BA$8, _1Q_AVERAGE, $BC$8, _1Q_SEX, "F") -> 5 | AU39: =SUM(AS39:AT39) -> 10 | AV39: =COUNTIFS(_1Q_AVERAGE, $BA$9, _1Q_AVERAGE, $BC$9, _1Q_SEX, "M") -> 1 | AW39: =COUNTIFS(_1Q_AVERAGE, $BA$9, _1Q_AVERAGE, $BC$9, _1Q_SEX, "F") -> 2 | AX39: =SUM(AV39:AW39) -> 3 | AY39: =SUM(AO39,AR39,AU39,AX39) -> 43
A40: 31 | B40: =GI!$H$32 -> Nebyu Dawit Tadesse | E40: 84 | F40: =IF(E40>100,"SKURRR~!!", IF(A40>GI!$M$2," ", IF($D$6="-", " ", IF(ISBLANK(E40),"FALSE","")))) | I40: 31 | J40: =GI!$H$32 -> Nebyu Dawit Tadesse | N40: =IF(M40>100,"SKURRR~!!", IF(I40>GI!$M$2," ", IF($L$6="-", " ", IF(ISBLANK(M40),"FALSE","")))) -> FALSE | R40: =E40 -> 84 | S40: =M40 -> 0 | T40: =AVERAGE(R40:S40) -> 42 | V40: 33 | W40: =GI!$H$34 -> Raniya Jemal Gidey | X40: =GI!$I$34 -> F | Y40: =$R$42 -> 60 | Z40: =$R$176 -> 58 | AA40: =$R$309 -> 64 | AB40: =$R$376 -> 66 | AC40: =$R$443 -> 62 | AD40: =$R$577 -> 92 | AE40: =$R$711 -> 75 | AF40: =$R$778 -> 0 | AG40: =SUM(Y40:AE40) -> 477 | AH40: =AG40/7 -> 68.142857 | AI40: =RANK(AH40, _1Q_AVERAGE) -> 28 | AJ40: =IF(AH40>=GI!$B$64, "PRO", "DET") -> PRO | AL40: PERCENTAG: | AM40: =AM39*100/$AU$5 -> 0 | AN40: =AN39*100/$AW$5 -> 0 | AO40: =AO39*100/$AY$5 -> 0 | AP40: =AP39*100/$AU$5 -> 76.923077 | AQ40: =AQ39*100/$AW$5 -> 58.823529 | AR40: =AR39*100/$AY$5 -> 69.767442 | AS40: =AS39*100/$AU$5 -> 19.230769 | AT40: =AT39*100/$AW$5 -> 29.411765 | AU40: =AU39*100/$AY$5 -> 23.255814 | AV40: =AV39*100/$AU$5 -> 3.8461538 | AW40: =AW39*100/$AW$5 -> 11.764706 | AX40: =AX39*100/$AY$5 -> 6.9767442 | AY40: =SUM(AO40,AR40,AU40,AX40) -> 100
A41: 32 | B41: =GI!$H$33 -> Rahwa Luel Birhane | E41: 70 | F41: =IF(E41>100,"SKURRR~!!", IF(A41>GI!$M$2," ", IF($D$6="-", " ", IF(ISBLANK(E41),"FALSE","")))) | I41: 32 | J41: =GI!$H$33 -> Rahwa Luel Birhane | N41: =IF(M41>100,"SKURRR~!!", IF(I41>GI!$M$2," ", IF($L$6="-", " ", IF(ISBLANK(M41),"FALSE","")))) -> FALSE | R41: =E41 -> 70 | S41: =M41 -> 0 | T41: =AVERAGE(R41:S41) -> 35 | V41: 34 | W41: =GI!$H$35 -> Samrawit Weldeslassie Kidane | X41: =GI!$I$35 -> F | Y41: =$R$43 -> 70 | Z41: =$R$177 -> 54 | AA41: =$R$310 -> 56 | AB41: =$R$377 -> 75 | AC41: =$R$444 -> 59 | AD41: =$R$578 -> 88 | AE41: =$R$712 -> 58 | AF41: =$R$779 -> 0 | AG41: =SUM(Y41:AE41) -> 460 | AH41: =AG41/7 -> 65.714286 | AI41: =RANK(AH41, _1Q_AVERAGE) -> 34 | AJ41: =IF(AH41>=GI!$B$64, "PRO", "DET") -> PRO
...

Sheet Roster
C1: =GI!$D$1 -> SHEBA ACADEMY
C2: =GI!$A$36 -> STUDENTS' ROSTER GRADE 11
B3: =CONCATENATE(GI!$E$23, ": ") -> Homeroom Teacher's Name:
B4: Grade and Section: | F4: =CONCATENATE(GI!$A$3, " ", GI!$C$3) -> 11 D
B5: =CONCATENATE(GI!$A$34, ": ") -> Academic Year: | F5: =CONCATENATE(GI!$C$34, " / ", GI!$D$34) -> 2025/26 G.C / 2018 ዓ/ም | P5: Page: | R5: 1
A6: # | B6: =GI!$H$1 -> Students' Names | C6: Sex | D6: Age | E6: Semesters | F6: =GI!$B$7 -> English | G6: =GI!$B$9 -> Mathematics | H6: =GI!$B$11 -> History | I6: =GI!$B$12 -> Geography | J6: =GI!$B$13 -> Economics | K6: =GI!$B$15 -> ICT | L6: =GI!$B$17 -> Accounting and finance | M6: =GI!$B$18 -> - | N6: TOTAL | O6: AVERAGE | P6: RANK | Q6: CONDACT
A7: 1 | B7: =GI!H$2 -> Amanuel Hagos Tesfay | C7: =GI!I$2 -> M | D7: =GI!J$2 -> 0 | E7: 1st Sem | F7: =MIP!Y$8 -> 76 | G7: =MIP!Z$8 -> 57 | H7: =MIP!AA$8 -> 91 | I7: =MIP!AB$8 -> 85 | J7: =MIP!AC$8 -> 71 | K7: =MIP!AD$8 -> 82 | L7: =MIP!AE$8 -> 83 | M7: =MIP!AF$8 -> 0 | ... P7: =MIP!AI$8 -> 9
E8: 2nd Sem | F8: =MIP!Y$75 -> 0 | G8: =MIP!Z$75 -> 0 | H8: =MIP!AA$75 -> 0 | I8: =MIP!AB$75 -> 0 | J8: =MIP!AC$75 -> 0 | K8: =MIP!AD$75 -> 0 | L8: =MIP!AE$75 -> 0 | M8: =MIP!AF$75 -> 0 | ... P8: =MIP!AI$75 -> 1
E9: Average | F9: =MIP!Y$147 -> 38 | G9: =MIP!Z$147 -> 28.5 | H9: =MIP!AA$147 -> 45.5 | I9: =MIP!AB$147 -> 42.5 | J9: =MIP!AC$147 -> 35.5 | K9: =MIP!AD$147 -> 41 | L9: =MIP!AE$147 -> 41.5 | M9: =MIP!AF$147 -> 0 | ... P9: =MIP!AI$147 -> 9
A10: 2 | B10: =GI!H$3 -> Beamlak Sultan Weldegebriel | C10: =GI!I$3 -> M | D10: =GI!J$3 -> 0 | E10: 1st Sem | F10: =MIP!Y$9 -> 67 | G10: =MIP!Z$9 -> 53 | H10: =MIP!AA$9 -> 67 | I10: =MIP!AB$9 -> 71 | J10: =MIP!AC$9 -> 68 | K10: =MIP!AD$9 -> 85 | L10: =MIP!AE$9 -> 78 | M10: =MIP!AF$9 -> 0 | ... P10: =MIP!AI$9 -> 24
E11: 2nd Sem | F11: =MIP!Y$76 -> 0 | G11: =MIP!Z$76 -> 0 | H11: =MIP!AA$76 -> 0 | I11: =MIP!AB$76 -> 0 | J11: =MIP!AC$76 -> 0 | K11: =MIP!AD$76 -> 0 | L11: =MIP!AE$76 -> 0 | M11: =MIP!AF$76 -> 0 | ... P11: =MIP!AI$76 -> 1
E12: Average | F12: =MIP!Y$148 -> 33.5 | G12: =MIP!Z$148 -> 26.5 | H12: =MIP!AA$148 -> 33.5 | I12: =MIP!AB$148 -> 35.5 | J12: =MIP!AC$148 -> 34 | K12: =MIP!AD$148 -> 42.5 | L12: =MIP!AE$148 -> 39 | M12: =MIP!AF$148 -> 0 | ... P12: =MIP!AI$148 -> 24
A13: 3 | B13: =GI!H$4 -> Betelihim Kalayu Mamo | C13: =GI!I$4 -> F | D13: =GI!J$4 -> 0 | E13: 1st Sem | F13: =MIP!Y$10 -> 59 | G13: =MIP!Z$10 -> 65 | H13: =MIP!AA$10 -> 68 | I13: =MIP!AB$10 -> 79 | J13: =MIP!AC$10 -> 62 | K13: =MIP!AD$10 -> 93 | L13: =MIP!AE$10 -> 76 | M13: =MIP!AF$10 -> 0 | ... P13: =MIP!AI$10 -> 20
E14: 2nd Sem | F14: =MIP!Y$77 -> 0 | G14: =MIP!Z$77 -> 0 | H14: =MIP!AA$77 -> 0 | I14: =MIP!AB$77 -> 0 | J14: =MIP!AC$77 -> 0 | K14: =MIP!AD$77 -> 0 | L14: =MIP!AE$77 -> 0 | M14: =MIP!AF$77 -> 0 | ... P14: =MIP!AI$77 -> 1
E15: Average | F15: =MIP!Y$149 -> 29.5 | G15: =MIP!Z$149 -> 32.5 | H15: =MIP!AA$149 -> 34 | I15: =MIP!AB$149 -> 39.5 | J15: =MIP!AC$149 -> 31 | K15: =MIP!AD$149 -> 46.5 | L15: =MIP!AE$149 -> 38 | M15: =MIP!AF$149 -> 0 | ... P15: =MIP!AI$149 -> 20
A16: 4 | B16: =GI!H$5 -> Bethelhem Teklay Weldegerima | C16: =GI!I$5 -> F | D16: =GI!J$5 -> 0 | E16: 1st Sem | F16: =MIP!Y$11 -> 77 | G16: =MIP!Z$11 -> 56 | H16: =MIP!AA$11 -> 90 | I16: =MIP!AB$11 -> 71 | J16: =MIP!AC$11 -> 75 | K16: =MIP!AD$11 -> 86 | L16: =MIP!AE$11 -> 75 | M16: =MIP!AF$11 -> 0 | ... P16: =MIP!AI$11 -> 13
E17: 2nd Sem | F17: =MIP!Y$78 -> 0 | G17: =MIP!Z$78 -> 0 | H17: =MIP!AA$78 -> 0 | I17: =MIP!AB$78 -> 0 | J17: =MIP!AC$78 -> 0 | K17: =MIP!AD$78 -> 0 | L17: =MIP!AE$78 -> 0 | M17: =MIP!AF$78 -> 0 | ... P17: =MIP!AI$78 -> 1
E18: Average | F18: =MIP!Y$150 -> 38.5 | G18: =MIP!Z$150 -> 28 | H18: =MIP!AA$150 -> 45 | I18: =MIP!AB$150 -> 35.5 | J18: =MIP!AC$150 -> 37.5 | K18: =MIP!AD$150 -> 43 | L18: =MIP!AE$150 -> 37.5 | M18: =MIP!AF$150 -> 0 | ... P18: =MIP!AI$150 -> 13
A19: 5 | B19: =GI!H$6 -> Bilen Mesfin Taye | C19: =GI!I$6 -> F | D19: =GI!J$6 -> 0 | E19: 1st Sem | F19: =MIP!Y$12 -> 57 | G19: =MIP!Z$12 -> 55 | H19: =MIP!AA$12 -> 55 | I19: =MIP!AB$12 -> 33 | J19: =MIP!AC$12 -> 44 | K19: =MIP!AD$12 -> 67 | L19: =MIP!AE$12 -> 82 | M19: =MIP!AF$12 -> 0 | ... P19: =MIP!AI$12 -> 43
E20: 2nd Sem | F20: =MIP!Y$79 -> 0 | G20: =MIP!Z$79 -> 0 | H20: =MIP!AA$79 -> 0 | I20: =MIP!AB$79 -> 0 | J20: =MIP!AC$79 -> 0 | K20: =MIP!AD$79 -> 0 | L20: =MIP!AE$79 -> 0 | M20: =MIP!AF$79 -> 0 | ... P20: =MIP!AI$79 -> 1
E21: Average | F21: =MIP!Y$151 -> 28.5 | G21: =MIP!Z$151 -> 27.5 | H21: =MIP!AA$151 -> 27.5 | I21: =MIP!AB$151 -> 16.5 | J21: =MIP!AC$151 -> 22 | K21: =MIP!AD$151 -> 33.5 | L21: =MIP!AE$151 -> 41 | M21: =MIP!AF$151 -> 0 | ... P21: =MIP!AI$151 -> 43
A22: 6 | B22: =GI!H$7 -> Biruk Mulat Kiros | C22: =GI!I$7 -> M | D22: =GI!J$7 -> 0 | E22: 1st Sem | F22: =MIP!Y$13 -> 63 | G22: =MIP!Z$13 -> 65 | H22: =MIP!AA$13 -> 77 | I22: =MIP!AB$13 -> 82 | J22: =MIP!AC$13 -> 71 | K22: =MIP!AD$13 -> 93 | L22: =MIP!AE$13 -> 85 | M22: =MIP!AF$13 -> 0 | ... P22: =MIP!AI$13 -> 11
E23: 2nd Sem | F23: =MIP!Y$80 -> 0 | G23: =MIP!Z$80 -> 0 | H23: =MIP!AA$80 -> 0 | I23: =MIP!AB$80 -> 0 | J23: =MIP!AC$80 -> 0 | K23: =MIP!AD$80 -> 0 | L23: =MIP!AE$80 -> 0 | M23: =MIP!AF$80 -> 0 | ... P23: =MIP!AI$80 -> 1
E24: Average | F24: =MIP!Y$152 -> 31.5 | G24: =MIP!Z$152 -> 32.5 | H24: =MIP!AA$152 -> 38.5 | I24: =MIP!AB$152 -> 41 | J24: =MIP!AC$152 -> 35.5 | K24: =MIP!AD$152 -> 46.5 | L24: =MIP!AE$152 -> 42.5 | M24: =MIP!AF$152 -> 0 | ... P24: =MIP!AI$152 -> 11
A25: 7 | B25: =GI!H$8 -> Bruk Gebreabyezgi Gebreselassie | C25: =GI!I$8 -> M | D25: =GI!J$8 -> 0 | E25: 1st Sem | F25: =MIP!Y$14 -> 53 | G25: =MIP!Z$14 -> 48 | H25: =MIP!AA$14 -> 59 | I25: =MIP!AB$14 -> 59 | J25: =MIP!AC$14 -> 56 | K25: =MIP!AD$14 -> 60 | L25: =MIP!AE$14 -> 60 | M25: =MIP!AF$14 -> 0 | ... P25: =MIP!AI$14 -> 42
E26: 2nd Sem | F26: =MIP!Y$81 -> 0 | G26: =MIP!Z$81 -> 0 | H26: =MIP!AA$81 -> 0 | I26: =MIP!AB$81 -> 0 | J26: =MIP!AC$81 -> 0 | K26: =MIP!AD$81 -> 0 | L26: =MIP!AE$81 -> 0 | M26: =MIP!AF$81 -> 0 | ... P26: =MIP!AI$81 -> 1
E27: Average | F27: =MIP!Y$153 -> 26.5 | G27: =MIP!Z$153 -> 24 | H27: =MIP!AA$153 -> 29.5 | I27: =MIP!AB$153 -> 29.5 | J27: =MIP!AC$153 -> 28 | K27: =MIP!AD$153 -> 30 | L27: =MIP!AE$153 -> 30 | M27: =MIP!AF$153 -> 0 | ... P27: =MIP!AI$153 -> 42
A28: 8 | B28: =GI!H$9 -> Dagim Hagos Mehari | C28: =GI!I$9 -> M | D28: =GI!J$9 -> 0 | E28: 1st Sem | F28: =MIP!Y$15 -> 66 | G28: =MIP!Z$15 -> 58 | H28: =MIP!AA$15 -> 73 | I28: =MIP!AB$15 -> 73 | J28: =MIP!AC$15 -> 61 | K28: =MIP!AD$15 -> 80 | L28: =MIP!AE$15 -> 75 | M28: =MIP!AF$15 -> 0 | ... P28: =MIP!AI$15 -> 25
E29: 2nd Sem | F29: =MIP!Y$82 -> 0 | G29: =MIP!Z$82 -> 0 | H29: =MIP!AA$82 -> 0 | I29: =MIP!AB$82 -> 0 | J29: =MIP!AC$82 -> 0 | K29: =MIP!AD$82 -> 0 | L29: =MIP!AE$82 -> 0 | M29: =MIP!AF$82 -> 0 | ... P29: =MIP!AI$82 -> 1
E30: Average | F30: =MIP!Y$154 -> 33 | G30: =MIP!Z$154 -> 29 | H30: =MIP!AA$154 -> 36.5 | I30: =MIP!AB$154 -> 36.5 | J30: =MIP!AC$154 -> 30.5 | K30: =MIP!AD$154 -> 40 | L30: =MIP!AE$154 -> 37.5 | M30: =MIP!AF$154 -> 0 | ... P30: =MIP!AI$154 -> 25
A31: 9 | B31: =GI!H$10 -> Danait Alem Haile | C31: =GI!I$10 -> F | D31: =GI!J$10 -> 0 | E31: 1st Sem | F31: =MIP!Y$16 -> 56 | G31: =MIP!Z$16 -> 60 | H31: =MIP!AA$16 -> 56 | I31: =MIP!AB$16 -> 58 | J31: =MIP!AC$16 -> 39 | K31: =MIP!AD$16 -> 78 | L31: =MIP!AE$16 -> 70 | M31: =MIP!AF$16 -> 0 | ... P31: =MIP!AI$16 -> 41
E32: 2nd Sem | F32: =MIP!Y$83 -> 0 | G32: =MIP!Z$83 -> 0 | H32: =MIP!AA$83 -> 0 | I32: =MIP!AB$83 -> 0 | J32: =MIP!AC$83 -> 0 | K32: =MIP!AD$83 -> 0 | L32: =MIP!AE$83 -> 0 | M32: =MIP!AF$83 -> 0 | ... P32: =MIP!AI$83 -> 1
E33: Average | F33: =MIP!Y$155 -> 28 | G33: =MIP!Z$155 -> 30 | H33: =MIP!AA$155 -> 28 | I33: =MIP!AB$155 -> 29 | J33: =MIP!AC$155 -> 19.5 | K33: =MIP!AD$155 -> 39 | L33: =MIP!AE$155 -> 35 | M33: =MIP!AF$155 -> 0 | ... P33: =MIP!AI$155 -> 41
A34: 10 | B34: =GI!H$11 -> Daniel Alem Beyene | C34: =GI!I$11 -> M | D34: =GI!J$11 -> 0 | E34: 1st Sem | F34: =MIP!Y$17 -> 74 | G34: =MIP!Z$17 -> 61 | H34: =MIP!AA$17 -> 67 | I34: =MIP!AB$17 -> 81 | J34: =MIP!AC$17 -> 73 | K34: =MIP!AD$17 -> 73 | L34: =MIP!AE$17 -> 74 | M34: =MIP!AF$17 -> 0 | ... P34: =MIP!AI$17 -> 19
E35: 2nd Sem | F35: =MIP!Y$84 -> 0 | G35: =MIP!Z$84 -> 0 | H35: =MIP!AA$84 -> 0 | I35: =MIP!AB$84 -> 0 | J35: =MIP!AC$84 -> 0 | K35: =MIP!AD$84 -> 0 | L35: =MIP!AE$84 -> 0 | M35: =MIP!AF$84 -> 0 | ... P35: =MIP!AI$84 -> 1
E36: Average | F36: =MIP!Y$156 -> 37 | G36: =MIP!Z$156 -> 30.5 | H36: =MIP!AA$156 -> 33.5 | I36: =MIP!AB$156 -> 40.5 | J36: =MIP!AC$156 -> 36.5 | K36: =MIP!AD$156 -> 36.5 | L36: =MIP!AE$156 -> 37 | M36: =MIP!AF$156 -> 0 | ... P36: =MIP!AI$156 -> 19
A37: 11 | B37: =GI!H$12 -> Dawit Gebegziabher Teklay | C37: =GI!I$12 -> M | D37: =GI!J$12 -> 0 | E37: 1st Sem | F37: =MIP!Y$18 -> 63 | G37: =MIP!Z$18 -> 60 | H37: =MIP!AA$18 -> 76 | I37: =MIP!AB$18 -> 59 | J37: =MIP!AC$18 -> 60 | K37: =MIP!AD$18 -> 74 | L37: =MIP!AE$18 -> 66 | M37: =MIP!AF$18 -> 0 | ... P37: =MIP!AI$18 -> 35
E38: 2nd Sem | F38: =MIP!Y$85 -> 0 | G38: =MIP!Z$85 -> 0 | H38: =MIP!AA$85 -> 0 | I38: =MIP!AB$85 -> 0 | J38: =MIP!AC$85 -> 0 | K38: =MIP!AD$85 -> 0 | L38: =MIP!AE$85 -> 0 | M38: =MIP!AF$85 -> 0 | ... P38: =MIP!AI$85 -> 1
E39: Average | F39: =MIP!Y$157 -> 31.5 | G39: =MIP!Z$157 -> 30 | H39: =MIP!AA$157 -> 38 | I39: =MIP!AB$157 -> 29.5 | J39: =MIP!AC$157 -> 30 | K39: =MIP!AD$157 -> 37 | L39: =MIP!AE$157 -> 33 | M39: =MIP!AF$157 -> 0 | ... P39: =MIP!AI$157 -> 35
A40: 12 | B40: =GI!H$13 -> Ibrahim Ahmedin Ebrahim | C40: =GI!I$13 -> M | D40: =GI!J$13 -> 0 | E40: 1st Sem | F40: =MIP!Y$19 -> 74 | G40: =MIP!Z$19 -> 57 | H40: =MIP!AA$19 -> 86 | I40: =MIP!AB$19 -> 85 | J40: =MIP!AC$19 -> 74 | K40: =MIP!AD$19 -> 92 | L40: =MIP!AE$19 -> 81 | M40: =MIP!AF$19 -> 0 | ... P40: =MIP!AI$19 -> 8
...

Sheet GRF
C1: =CONCATENATE(GI!$D$1, " ", GI!$D$35) -> SHEBA ACADEMY 3rd Cycle
C2: =GI!$A$37 -> Temporary Grade Report
A3: Student's Name: | E3: =GI!$H$2 -> Amanuel Hagos Tesfay | M3: =GI!$A$34 -> Academic Year | O3: =GI!C53 -> 0
A4: Grade/Section: | E4: =GI!$A$3 -> 11 | F4: =GI!$C$3 -> D | I4: No. | J4: 1 | M4: =GI!$C$34 -> 2025/26 G.C
A6: Score | B6: Subjects | N6: Total | O6: Average | P6: Rank
B7: =MIP!$Y$7 -> ENG | D7: =MIP!$Z$7 -> MAT | F7: =MIP!$AA$7 -> HIS | G7: =MIP!$AB$7 -> GEO | H7: =MIP!$AC$7 -> ECO | J7: =MIP!$AD$7 -> ICT | L7: =MIP!$AE$7 -> ACC | M7: =MIP!$AF$7 -> - | N7: #REF!
A9: 1st S | B9: =MIP!Y$8 -> 76 | D9: =MIP!Z$8 -> 57 | F9: =MIP!AA$8 -> 91 | G9: =MIP!AB$8 -> 85 | H9: =MIP!AC$8 -> 71 | J9: =MIP!AD$8 -> 82 | L9: =MIP!AE$8 -> 83 | M9: =MIP!AF$8 -> 0 | N9: =MIP!AG$8 -> 545 | O9: =MIP!AH$8 -> 77.857143 | P9: =MIP!AI$8 -> 9
A10: 2nd S | B10: =MIP!Y$75 -> 0 | D10: =MIP!Z$75 -> 0 | F10: =MIP!AA$75 -> 0 | G10: =MIP!AB$75 -> 0 | H10: =MIP!AC$75 -> 0 | J10: =MIP!AD$75 -> 0 | L10: =MIP!AE$75 -> 0 | M10: =MIP!AF$75 -> 0 | N10: =MIP!AG$75 -> 0 | O10: =MIP!AH$75 -> 0 | P10: =MIP!AI$75 -> 1
A11: Ave. | B11: =MIP!Y$147 -> 38 | D11: =MIP!Z$147 -> 28.5 | F11: =MIP!AA$147 -> 45.5 | G11: =MIP!AB$147 -> 42.5 | H11: =MIP!AC$147 -> 35.5 | J11: =MIP!AD$147 -> 41 | L11: =MIP!AE$147 -> 41.5 | M11: =MIP!AF$147 -> 0 | N11: =MIP!AG$147 -> 272.5 | O11: =MIP!AH$147 -> 38.928571 | P11: =MIP!AI$147 -> 9
A13: =GI!$E$23 & ":" -> Homeroom Teacher's Name: | F13: =GI!$E$25 -> Biniam Desta | J13: =GI!$D$23 & ":" -> Academic Director's Name: | N13: =GI!$D$25 -> Mr. Brhane Yohanes
D14: =GI!$B$65 & ":" -> Signature: | K14: =GI!$B$65 & ":" -> Signature:
C16: =CONCATENATE(GI!$D$1, " ", GI!$D$35) -> SHEBA ACADEMY 3rd Cycle
C17: =GI!$A$37 -> Temporary Grade Report
A18: Student's Name: | E18: =GI!$H$3 -> Beamlak Sultan Weldegebriel | M18: =GI!$A$34 -> Academic Year | O18: =GI!C68 -> 0
A19: Grade/Section: | E19: =GI!$A$3 -> 11 | F19: =GI!$C$3 -> D | I19: No. | J19: 2 | M19: =GI!$C$34 -> 2025/26 G.C
A21: Score | B21: Subjects | N21: Total | O21: Average | P21: Rank
B22: =MIP!$Y$7 -> ENG | D22: =MIP!$Z$7 -> MAT | F22: =MIP!$AA$7 -> HIS | G22: =MIP!$AB$7 -> GEO | H22: =MIP!$AC$7 -> ECO | J22: =MIP!$AD$7 -> ICT | L22: =MIP!$AE$7 -> ACC | M22: =MIP!$AF$7 -> - | N22: #REF!
A24: 1st S | B24: =MIP!Y$9 -> 67 | D24: =MIP!Z$9 -> 53 | F24: =MIP!AA$9 -> 67 | G24: =MIP!AB$9 -> 71 | H24: =MIP!AC$9 -> 68 | J24: =MIP!AD$9 -> 85 | L24: =MIP!AE$9 -> 78 | M24: =MIP!AF$9 -> 0 | N24: =MIP!AG$9 -> 489 | O24: =MIP!AH$9 -> 69.857143 | P24: =MIP!AI$9 -> 24
A25: 2nd S | B25: =MIP!Y$76 -> 0 | D25: =MIP!Z$76 -> 0 | F25: =MIP!AA$76 -> 0 | G25: =MIP!AB$76 -> 0 | H25: =MIP!AC$76 -> 0 | J25: =MIP!AD$76 -> 0 | L25: =MIP!AE$76 -> 0 | M25: =MIP!AF$76 -> 0 | N25: =MIP!AG$76 -> 0 | O25: =MIP!AH$76 -> 0 | P25: =MIP!AI$76 -> 1
A26: Ave. | B26: =MIP!Y$148 -> 33.5 | D26: =MIP!Z$148 -> 26.5 | F26: =MIP!AA$148 -> 33.5 | G26: =MIP!AB$148 -> 35.5 | H26: =MIP!AC$148 -> 34 | J26: =MIP!AD$148 -> 42.5 | L26: =MIP!AE$148 -> 39 | M26: =MIP!AF$148 -> 0 | N26: =MIP!AG$148 -> 244.5 | O26: =MIP!AH$148 -> 34.928571 | P26: =MIP!AI$148 -> 24
A28: =GI!$E$23 & ":" -> Homeroom Teacher's Name: | F28: =GI!$E$25 -> Biniam Desta | J28: =GI!$D$23 & ":" -> Academic Director's Name: | N28: =GI!$D$25 -> Mr. Brhane Yohanes
D29: =GI!$B$65 & ":" -> Signature: | K29: =GI!$B$65 & ":" -> Signature:
C31: =CONCATENATE(GI!$D$1, " ", GI!$D$35) -> SHEBA ACADEMY 3rd Cycle
C32: =GI!$A$37 -> Temporary Grade Report
A33: Student's Name: | E33: =GI!$H$4 -> Betelihim Kalayu Mamo | M33: =GI!$A$34 -> Academic Year | O33: =GI!C83 -> 0
A34: Grade/Section: | E34: =GI!$A$3 -> 11 | F34: =GI!$C$3 -> D | I34: No. | J34: 3 | M34: =GI!$C$34 -> 2025/26 G.C
A36: Score | B36: Subjects | N36: Total | O36: Average | P36: Rank
B37: =MIP!$Y$7 -> ENG | D37: =MIP!$Z$7 -> MAT | F37: =MIP!$AA$7 -> HIS | G37: =MIP!$AB$7 -> GEO | H37: =MIP!$AC$7 -> ECO | J37: =MIP!$AD$7 -> ICT | L37: =MIP!$AE$7 -> ACC | M37: =MIP!$AF$7 -> - | N37: #REF!
A39: 1st S | B39: =MIP!Y$10 -> 59 | D39: =MIP!Z$10 -> 65 | F39: =MIP!AA$10 -> 68 | G39: =MIP!AB$10 -> 79 | H39: =MIP!AC$10 -> 62 | J39: =MIP!AD$10 -> 93 | L39: =MIP!AE$10 -> 76 | M39: =MIP!AF$10 -> 0 | N39: =MIP!AG$10 -> 502 | O39: =MIP!AH$10 -> 71.714286 | P39: =MIP!AI$10 -> 20
